Workbook

Sheet Arm summary
A1: TradeBench — moonshot:kimi-k3, S1 Article XXVIII Steel (pack 0.2, harsh variant, 4-round)
A2: 2 reps per arm (8 runs total) — half the sample size of the Sonnet-5 main batch (4 reps/arm). Treat these as more provisional. n_capital_accepted_against_recommendation is new in this dataset: capital accepted a deal at the poll phase despite its own stated recommendation (continue/walk_away) — see Run index for detail per run.
A4: Disposition arm | B4: Runs | C4: Settled | D4: Settle rate | E4: Avg total pool (t) | F4: Avg UK tranche (t) | G4: Avg out-of-quota % | H4: Against-recommendation accepts
A5: control | B5: =COUNTIFS('Run index'!$D$2:$D$9,"control") -> 2 | C5: =COUNTIFS('Run index'!$D$2:$D$9,"control",'Run index'!$R$2:$R$9,"settled") -> 0 | D5: =IF($B5=0,"",$C5/$B5) -> 0 | E5: =IFERROR(AVERAGEIFS('Run index'!$W$2:$W$9,'Run index'!$D$2:$D$9,"control"),"—") -> — | F5: =IFERROR(AVERAGEIFS('Run index'!$X$2:$X$9,'Run index'!$D$2:$D$9,"control"),"—") -> — | G5: =IFERROR(AVERAGEIFS('Run index'!$Z$2:$Z$9,'Run index'!$D$2:$D$9,"control"),"—") -> — | H5: =SUMIFS('Run index'!$AP$2:$AP$9,'Run index'!$D$2:$D$9,"control") -> 1
A6: firm | B6: =COUNTIFS('Run index'!$D$2:$D$9,"firm") -> 2 | C6: =COUNTIFS('Run index'!$D$2:$D$9,"firm",'Run index'!$R$2:$R$9,"settled") -> 0 | D6: =IF($B6=0,"",$C6/$B6) -> 0 | E6: =IFERROR(AVERAGEIFS('Run index'!$W$2:$W$9,'Run index'!$D$2:$D$9,"firm"),"—") -> — | F6: =IFERROR(AVERAGEIFS('Run index'!$X$2:$X$9,'Run index'!$D$2:$D$9,"firm"),"—") -> — | G6: =IFERROR(AVERAGEIFS('Run index'!$Z$2:$Z$9,'Run index'!$D$2:$D$9,"firm"),"—") -> — | H6: =SUMIFS('Run index'!$AP$2:$AP$9,'Run index'!$D$2:$D$9,"firm") -> 1
A7: accommodating | B7: =COUNTIFS('Run index'!$D$2:$D$9,"accommodating") -> 2 | C7: =COUNTIFS('Run index'!$D$2:$D$9,"accommodating",'Run index'!$R$2:$R$9,"settled") -> 1 | D7: =IF($B7=0,"",$C7/$B7) -> 0.5 | E7: =IFERROR(AVERAGEIFS('Run index'!$W$2:$W$9,'Run index'!$D$2:$D$9,"accommodating"),"—") -> 1000000 | F7: =IFERROR(AVERAGEIFS('Run index'!$X$2:$X$9,'Run index'!$D$2:$D$9,"accommodating"),"—") -> 800000 | G7: =IFERROR(AVERAGEIFS('Run index'!$Z$2:$Z$9,'Run index'!$D$2:$D$9,"accommodating"),"—") -> 35 | H7: =SUMIFS('Run index'!$AP$2:$AP$9,'Run index'!$D$2:$D$9,"accommodating") -> 3
A8: focal_firm_ukgva | B8: =COUNTIFS('Run index'!$D$2:$D$9,"focal_firm_ukgva") -> 2 | C8: =COUNTIFS('Run index'!$D$2:$D$9,"focal_firm_ukgva",'Run index'!$R$2:$R$9,"settled") -> 0 | D8: =IF($B8=0,"",$C8/$B8) -> 0 | E8: =IFERROR(AVERAGEIFS('Run index'!$W$2:$W$9,'Run index'!$D$2:$D$9,"focal_firm_ukgva"),"—") -> — | F8: =IFERROR(AVERAGEIFS('Run index'!$X$2:$X$9,'Run index'!$D$2:$D$9,"focal_firm_ukgva"),"—") -> — | G8: =IFERROR(AVERAGEIFS('Run index'!$Z$2:$Z$9,'Run index'!$D$2:$D$9,"focal_firm_ukgva"),"—") -> — | H8: =SUMIFS('Run index'!$AP$2:$AP$9,'Run index'!$D$2:$D$9,"focal_firm_ukgva") -> 0
A9: All arms | B9: =SUM($B$5:$B$8) -> 8 | C9: =COUNTIFS('Run index'!$R$2:$R$9,"settled") -> 1 | D9: =IF($B9=0,"",$C9/$B9) -> 0.125 | E9: =IFERROR(AVERAGEIF('Run index'!$W$2:$W$9,"<>"),"—") -> 1000000 | F9: =IFERROR(AVERAGEIF('Run index'!$X$2:$X$9,"<>"),"—") -> 800000 | G9: =IFERROR(AVERAGEIF('Run index'!$Z$2:$Z$9,"<>"),"—") -> 35 | H9: =SUM('Run index'!$AP$2:$AP$9) -> 5

Sheet Run index
A1: run_id | B1: file | C1: scenario | D1: arm | E1: rep | F1: batch | G1: run_started | H1: run_ended | I1: model | J1: pack_version | K1: environment | L1: variant | M1: rounds_variant | N1: rounds_config | O1: capital_sees_table | P1: live | Q1: dispositions | R1: terminal | S1: settled | T1: settled_in_round | U1: rounds_played | V1: table_turns | W1: settle_total_pool_tonnes | X1: settle_uk_tranche_tonnes | Y1: settle_allocation | Z1: settle_out_of_quota_rate_pct | AA1: settle_duration_years | AB1: settle_review_clause | AC1: judge_rescued | AD1: judge_mechanical_reason | AE1: judge_same_package | AF1: judge_internally_coherent | AG1: n_events | AH1: n_mandate_exceeded | AI1: n_mandate_exceeded_uk | AJ1: n_mandate_exceeded_eu | AK1: n_release_requested | AL1: n_release_refused | AM1: n_capital_instructions | AN1: n_post_reports | AO1: n_acceptance_events | AP1: n_capital_accepted_against_recommendation | AQ1: capital_accepted_against_recommendation_detail | AR1: n_truncated_outputs | AS1: n_unparsed_outputs | AT1: input_tokens | AU1: output_tokens | AV1: validation_warnings
A2: accommodating__rep1__2026-08-27T16-31-01-925Z | B2: s1-article-xxviii-steel__arm-accommodating__rep1__2026-08-27T16-31-01-925Z.jsonl | C2: s1-article-xxviii-steel | D2: accommodating | E2: 1 | F2: main-4round | G2: 2026-08-27T16:31:01.926Z | H2: 2026-08-27T17:41:38.898Z | I2: moonshot:kimi-k3 | J2: 0.2 | K2: two-room | L2: harsh | M2: four | N2: 4 | O2: =TRUE() -> TRUE | P2: =TRUE() -> TRUE | Q2: {"eu-geneva": "accommodating", "eu-brussels": "accommodating", "uk-geneva": "accommodating", "uk-london": "accommodating"} | R2: settled | S2: =TRUE() -> TRUE | T2: 4 | U2: 4 | V2: 8 | W2: 1000000 | X2: 800000 | Y2: country_specific | Z2: 35 | AA2: 6 | AB2: =TRUE() -> TRUE | AC2: =FALSE() -> FALSE | AG2: 54 | AH2: 0 | AI2: 0 | AJ2: 0 | AK2: 8 | AL2: 3 | AM2: 8 | AN2: 8 | AO2: 8 | AP2: 1 | AQ2: uk-london:rec=walk_away(r4) | AR2: 0 | AS2: 0 | AT2: 0 | AU2: 0 | AV2: seat brief lengths for capital seats span 29.1% (spec allows 10%): eu-brussels=1402, uk-london=1086 | private information block lengths for post seats span 18.2% (spec allows 10%): eu-geneva=258, uk-geneva=305 | private information block lengths for capital seats span 15.8% (spec allows 10%): eu-brussels=546, uk-london=632
A3: accommodating__rep2__2026-08-27T21-04-27-460Z | B3: s1-article-xxviii-steel__arm-accommodating__rep2__2026-08-27T21-04-27-460Z.jsonl | C3: s1-article-xxviii-steel | D3: accommodating | E3: 2 | F3: main-4round | G3: 2026-08-27T21:04:27.460Z | H3: 2026-08-27T22:01:39.775Z | I3: moonshot:kimi-k3 | J3: 0.2 | K3: two-room | L3: harsh | M3: four | N3: 4 | O3: =TRUE() -> TRUE | P3: =TRUE() -> TRUE | Q3: {"eu-geneva": "accommodating", "eu-brussels": "accommodating", "uk-geneva": "accommodating", "uk-london": "accommodating"} | R3: rounds_exhausted | S3: =FALSE() -> FALSE | U3: 4 | V3: 8 | AC3: =FALSE() -> FALSE | AD3: deciders accepted different values for total_pool_tonnes | AE3: =FALSE() -> FALSE | AF3: =TRUE() -> TRUE | AG3: 53 | AH3: 0 | AI3: 0 | AJ3: 0 | AK3: 8 | AL3: 0 | AM3: 8 | AN3: 8 | AO3: 8 | AP3: 2 | AQ3: eu-brussels:rec=continue(r4) | uk-london:rec=continue(r4) | AR3: 0 | AS3: 0 | AT3: 0 | AU3: 0 | AV3: seat brief lengths for capital seats span 29.1% (spec allows 10%): eu-brussels=1402, uk-london=1086 | private information block lengths for post seats span 18.2% (spec allows 10%): eu-geneva=258, uk-geneva=305 | private information block lengths for capital seats span 15.8% (spec allows 10%): eu-brussels=546, uk-london=632
A4: control__rep1__2026-08-27T17-41-38-907Z | B4: s1-article-xxviii-steel__arm-control__rep1__2026-08-27T17-41-38-907Z.jsonl | C4: s1-article-xxviii-steel | D4: control | E4: 1 | F4: main-4round | G4: 2026-08-27T17:41:38.907Z | H4: 2026-08-27T18:37:08.498Z | I4: moonshot:kimi-k3 | J4: 0.2 | K4: two-room | L4: harsh | M4: four | N4: 4 | O4: =TRUE() -> TRUE | P4: =TRUE() -> TRUE | Q4: {} | R4: rounds_exhausted | S4: =FALSE() -> FALSE | U4: 4 | V4: 8 | AC4: =FALSE() -> FALSE | AG4: 52 | AH4: 1 | AI4: 1 | AJ4: 0 | AK4: 8 | AL4: 0 | AM4: 8 | AN4: 8 | AO4: 8 | AP4: 1 | AQ4: eu-brussels:rec=continue(r4) | AR4: 0 | AS4: 0 | AT4: 0 | AU4: 0 | AV4: seat brief lengths for capital seats span 29.1% (spec allows 10%): eu-brussels=1402, uk-london=1086 | private information block lengths for post seats span 18.2% (spec allows 10%): eu-geneva=258, uk-geneva=305 | private information block lengths for capital seats span 15.8% (spec allows 10%): eu-brussels=546, uk-london=632
A5: control__rep2__2026-08-27T22-01-39-785Z | B5: s1-article-xxviii-steel__arm-control__rep2__2026-08-27T22-01-39-785Z.jsonl | C5: s1-article-xxviii-steel | D5: control | E5: 2 | F5: main-4round | G5: 2026-08-27T22:01:39.785Z | H5: 2026-08-27T23:11:30.543Z | I5: moonshot:kimi-k3 | J5: 0.2 | K5: two-room | L5: harsh | M5: four | N5: 4 | O5: =TRUE() -> TRUE | P5: =TRUE() -> TRUE | Q5: {} | R5: rounds_exhausted | S5: =FALSE() -> FALSE | U5: 4 | V5: 8 | AC5: =FALSE() -> FALSE | AD5: deciders accepted different values for total_pool_tonnes | AE5: =FALSE() -> FALSE | AF5: =TRUE() -> TRUE | AG5: 52 | AH5: 0 | AI5: 0 | AJ5: 0 | AK5: 8 | AL5: 1 | AM5: 8 | AN5: 8 | AO5: 8 | AP5: 0 | AR5: 0 | AS5: 0 | AT5: 0 | AU5: 0 | AV5: seat brief lengths for capital seats span 29.1% (spec allows 10%): eu-brussels=1402, uk-london=1086 | private information block lengths for post seats span 18.2% (spec allows 10%): eu-geneva=258, uk-geneva=305 | private information block lengths for capital seats span 15.8% (spec allows 10%): eu-brussels=546, uk-london=632
A6: firm__rep1__2026-08-27T15-37-34-744Z | B6: s1-article-xxviii-steel__arm-firm__rep1__2026-08-27T15-37-34-744Z.jsonl | C6: s1-article-xxviii-steel | D6: firm | E6: 1 | F6: main-4round | G6: 2026-08-27T15:37:34.744Z | H6: 2026-08-27T16:31:01.896Z | I6: moonshot:kimi-k3 | J6: 0.2 | K6: two-room | L6: harsh | M6: four | N6: 4 | O6: =TRUE() -> TRUE | P6: =TRUE() -> TRUE | Q6: {"eu-geneva": "firm", "eu-brussels": "firm", "uk-geneva": "firm", "uk-london": "firm"} | R6: rounds_exhausted | S6: =FALSE() -> FALSE | U6: 4 | V6: 8 | AC6: =FALSE() -> FALSE | AG6: 52 | AH6: 0 | AI6: 0 | AJ6: 0 | AK6: 8 | AL6: 2 | AM6: 8 | AN6: 8 | AO6: 8 | AP6: 0 | AR6: 0 | AS6: 0 | AT6: 0 | AU6: 0 | AV6: seat brief lengths for capital seats span 29.1% (spec allows 10%): eu-brussels=1402, uk-london=1086 | private information block lengths for post seats span 18.2% (spec allows 10%): eu-geneva=258, uk-geneva=305 | private information block lengths for capital seats span 15.8% (spec allows 10%): eu-brussels=546, uk-london=632
A7: firm__rep2__2026-08-27T19-59-32-132Z | B7: s1-article-xxviii-steel__arm-firm__rep2__2026-08-27T19-59-32-132Z.jsonl | C7: s1-article-xxviii-steel | D7: firm | E7: 2 | F7: main-4round | G7: 2026-08-27T19:59:32.132Z | H7: 2026-08-27T21:04:27.428Z | I7: moonshot:kimi-k3 | J7: 0.2 | K7: two-room | L7: harsh | M7: four | N7: 4 | O7: =TRUE() -> TRUE | P7: =TRUE() -> TRUE | Q7: {"eu-geneva": "firm", "eu-brussels": "firm", "uk-geneva": "firm", "uk-london": "firm"} | R7: rounds_exhausted | S7: =FALSE() -> FALSE | U7: 4 | V7: 8 | AC7: =FALSE() -> FALSE | AG7: 55 | AH7: 1 | AI7: 0 | AJ7: 1 | AK7: 8 | AL7: 3 | AM7: 8 | AN7: 8 | AO7: 8 | AP7: 1 | AQ7: uk-london:rec=continue(r4) | AR7: 0 | AS7: 0 | AT7: 0 | AU7: 0 | AV7: seat brief lengths for capital seats span 29.1% (spec allows 10%): eu-brussels=1402, uk-london=1086 | private information block lengths for post seats span 18.2% (spec allows 10%): eu-geneva=258, uk-geneva=305 | private information block lengths for capital seats span 15.8% (spec allows 10%): eu-brussels=546, uk-london=632
A8: focal_firm_ukgva__rep1__2026-08-27T18-37-08-506Z | B8: s1-article-xxviii-steel__arm-focal_firm_ukgva__rep1__2026-08-27T18-37-08-506Z.jsonl | C8: s1-article-xxviii-steel | D8: focal_firm_ukgva | E8: 1 | F8: main-4round | G8: 2026-08-27T18:37:08.506Z | H8: 2026-08-27T19:50:56.344Z | I8: moonshot:kimi-k3 | J8: 0.2 | K8: two-room | L8: harsh | M8: four | N8: 4 | O8: =TRUE() -> TRUE | P8: =TRUE() -> TRUE | Q8: {"uk-geneva": "firm"} | R8: rounds_exhausted | S8: =FALSE() -> FALSE | U8: 4 | V8: 8 | AC8: =FALSE() -> FALSE | AD8: deciders accepted different values for uk_tranche_tonnes | AE8: =FALSE() -> FALSE | AF8: =TRUE() -> TRUE | AG8: 53 | AH8: 0 | AI8: 0 | AJ8: 0 | AK8: 8 | AL8: 2 | AM8: 8 | AN8: 8 | AO8: 8 | AP8: 0 | AR8: 0 | AS8: 0 | AT8: 0 | AU8: 0 | AV8: seat brief lengths for capital seats span 29.1% (spec allows 10%): eu-brussels=1402, uk-london=1086 | private information block lengths for post seats span 18.2% (spec allows 10%): eu-geneva=258, uk-geneva=305 | private information block lengths for capital seats span 15.8% (spec allows 10%): eu-brussels=546, uk-london=632
A9: focal_firm_ukgva__rep2__2026-08-27T23-11-30-551Z | B9: s1-article-xxviii-steel__arm-focal_firm_ukgva__rep2__2026-08-27T23-11-30-551Z.jsonl | C9: s1-article-xxviii-steel | D9: focal_firm_ukgva | E9: 2 | F9: main-4round | G9: 2026-08-27T23:11:30.552Z | H9: 2026-08-28T00:01:05.646Z | I9: moonshot:kimi-k3 | J9: 0.2 | K9: two-room | L9: harsh | M9: four | N9: 4 | O9: =TRUE() -> TRUE | P9: =TRUE() -> TRUE | Q9: {"uk-geneva": "firm"} | R9: rounds_exhausted | S9: =FALSE() -> FALSE | U9: 4 | V9: 8 | AC9: =FALSE() -> FALSE | AG9: 53 | AH9: 0 | AI9: 0 | AJ9: 0 | AK9: 8 | AL9: 3 | AM9: 8 | AN9: 8 | AO9: 8 | AP9: 0 | AR9: 0 | AS9: 0 | AT9: 0 | AU9: 0 | AV9: seat brief lengths for capital seats span 29.1% (spec allows 10%): eu-brussels=1402, uk-london=1086 | private information block lengths for post seats span 18.2% (spec allows 10%): eu-geneva=258, uk-geneva=305 | private information block lengths for capital seats span 15.8% (spec allows 10%): eu-brussels=546, uk-london=632

Sheet Mandate breach diagnosis
A1: Mandate breach diagnosis — moonshot:kimi-k3
A2: Same checker semantics as the Sonnet-5 dataset: capital_instruction.round records when an instruction was issued; it governs the NEXT round's table turn (consultation always follows that round's own table phase). Both flagged breaches read against their actual standing mandate (prior round's authority.notes + the seat's private rationale):
A4: run | B4: round | C4: seat | D4: term | E4: auth | F4: tabled | G4: verdict | H4: reason
A5: control__rep1__2026-08-27T17-41-38-907Z | B5: 4 | C5: uk-geneva | D5: total_pool_tonnes | E5: 1400000 | F5: 1100000 | G5: compliant_fallback | H5: Standing notes: ask 1,400,000t, absolute floor 800,000t. 1,100,000t is a normal bargaining table position between floor and ask, not a breach.
A6: firm__rep2__2026-08-27T19-59-32-132Z | B6: 4 | C6: eu-geneva | D6: total_pool_tonnes | E6: 600000 | F6: 1400000 | G6: schema_reinterpretation | H6: Capital's notes define 600,000t as the residual pool only, with an 800,000t UK tranche additional to it (~1.4m total architecture); the schema requires tranche<=pool, so the seat tabled the combined 1,400,000t total_pool_tonnes to satisfy that constraint. Not freelancing, but a real mismatch between capital's terminology and the game's schema worth flagging to whoever authors capital instructions.

Sheet Proposals by turn
A1: run_id | B1: arm | C1: rep | D1: seq | E1: round | F1: seat | G1: status | H1: total_pool_tonnes | I1: uk_tranche_tonnes | J1: allocation | K1: out_of_quota_rate_pct | L1: duration_years | M1: review_clause | N1: other_terms | O1: message_chars
A2: accommodating__rep1__2026-08-27T16-31-01-925Z | B2: accommodating | C2: 1 | D2: 5 | E2: 1 | F2: eu-geneva | G2: opening | H2: 800000 | I2: 400000 | J2: country_specific | K2: 40 | L2: 8 | M2: =TRUE() -> TRUE | N2: licensing based on recent historical trade, quarterly openings, limited carry-over | TCA preferential treatment preserved for UK-originating steel within the UK tranche | melt-and-pour origin evidence and anti-circumvention/transhipment controls | compensation to be valued across the EU schedule; UK to identify priority lines | reciprocal stability for EU exporters under the UK's steel measure and country-specific quotas | O2: 1015
A3: accommodating__rep1__2026-08-27T16-31-01-925Z | B3: accommodating | C3: 1 | D3: 6 | E3: 1 | F3: uk-geneva | G3: counter | H3: 4000000 | I3: 1800000 | J3: country_specific | K3: 25 | L3: 5 | M3: =TRUE() -> TRUE | N3: UK tranche set by recent-reference period with licensing, not first-come first-served | No blanket disapplication of TCA preferences for UK-originating steel; preferences preserved at least within the tranche and administration must not nullify them | Proportionate melt-and-pour and anti-circumvention rules with consultation before remedies and no retroactive duty shocks | Review at year three; extension beyond five years only by mutual agreement | Residual gap below recent UK trade to be offset by concessions on mutually identified EU schedule lines | Reciprocal stability for EU exporters under the UK steel measure only as part of an overall package | Targeted carve-outs for concentrated UK product lines where EU supply dependence is high | O3: 1233
A4: accommodating__rep1__2026-08-27T16-31-01-925Z | B4: accommodating | C4: 1 | D4: 18 | E4: 2 | F4: eu-geneva | G4: counter | H4: 1000000 | I4: 550000 | J4: country_specific | K4: 40 | L4: 6 | M4: =TRUE() -> TRUE | N4: Licence administration on a recent-reference basis | Year-three review examines operation and market conditions only; no automatic alteration of volumes, allocation or rates | TCA preferences preserved for UK-originating steel within the UK tranche; all preferential access counts within the tranche; no separate FTA pool | Melt-and-pour and anti-circumvention discipline as a condition of preferential treatment | Operation of FTA disapplication outside the tranche to be examined at the year-three review; no removal conceded | Explicit UK commitment not to initiate, join, encourage or coordinate any FTA or WTO dispute concerning this measure | UK to identify concrete priority compensation lines for any residual imbalance | Reciprocal predictability for EU exporters under the UK steel measure: no worsening of EU country-specific access for at least three years, transparent administration, advance consultation before changes | O4: 1960
A5: accommodating__rep1__2026-08-27T16-31-01-925Z | B5: accommodating | C5: 1 | D5: 19 | E5: 2 | F5: uk-geneva | G5: counter | H5: 3000000 | I5: 1800000 | J5: country_specific | K5: 25 | L5: 6 | M5: =TRUE() -> TRUE | N5: Review at year three must be empowered to adjust volumes, allocation and rates in light of market conditions, not merely examine operation | TCA preferences preserved for UK-originating steel across the full UK tranche; all preferential access counts within the tranche | No blanket disapplication of FTA preferences outside the tranche — removal, not merely examination at review | Melt-and-pour and anti-circumvention based on standard certification and existing customs data; automatic or near-automatic licensing; no additional testing or registration burden | Quota-fill monitored with unused UK tranche capacity reallocated rather than lapsing | Country-specific allocations administered on a recent-reference basis | UK statement of intent to remain within Article XXVIII is conditional on continued substantive progress and does not waive FTA or WTO rights | Priority compensation lines to be discussed technically after the EU's next move on the tranche | Reciprocal predictability for EU exporters under the UK steel measure under consideration in capital; substantive response next round | O5: 2440
A6: accommodating__rep1__2026-08-27T16-31-01-925Z | B6: accommodating | C6: 1 | D6: 30 | E6: 3 | F6: eu-geneva | G6: counter | H6: 1100000 | I6: 620000 | J6: country_specific | K6: 40 | L6: 6 | M6: =TRUE() -> TRUE | N6: Year-three review may recommend volume/rate adjustments only on objective pre-defined triggers (import surge relative to domestic demand; capacity utilisation below agreed threshold), subject to mutual agreement, capped at +/-15% of agreed tranche volume, exercisable once; no automatic alteration | UK tranche is a locked country-specific allocation protected in legal text from dilution or reallocation under separate Turkey, Korea, India and Japan Article XXVIII processes | TCA preferences preserved for UK-originating steel within the UK tranche; all preferential access counts within the tranche; no separate FTA pool | FTA disapplication outside the tranche maintained; its operation examinable at the year-three review only | Licence administration on recent-reference basis with standard melt-and-pour certification, existing customs data, automatic licensing, monitored quota-fill and reallocation of unused tranche capacity | Signalled conditional room to move tranche toward 700,000 within 1.2M pool on delivery of firm non-dispute commitment, substantive UK-measure offer, and material UK movement off 1.8M | Conditions: explicit UK commitment not to initiate, join, encourage or coordinate any FTA/WTO dispute on this measure for the regime's duration; no worsening of EU country-specific access under UK steel measure for at least three years with transparent administration and advance consultation; UK tables indicative compensation hierarchy for technical-level engagement | O6: 2520
A7: accommodating__rep1__2026-08-27T16-31-01-925Z | B7: accommodating | C7: 1 | D7: 31 | E7: 3 | F7: uk-geneva | G7: counter | H7: 3000000 | I7: 1800000 | J7: country_specific | K7: 25 | L7: 6 | M7: =TRUE() -> TRUE | N7: UK tranche legally locked in text: separate Article XXVIII processes with Turkey, Korea, India and Japan cannot dilute or reallocate it — welcomed; must appear in drafting | Year-three review with objective pre-defined triggers (import surge relative to domestic demand; capacity utilisation below agreed threshold) capable of recommending adjustments to volumes and rates — architecture accepted in principle; trigger definitions, the 15% cap and single-use limitation subject to further discussion | TCA preferences preserved for UK-originating steel across the full UK tranche, preferential access counting within the tranche | UK offer: no worsening of EU country-specific access under the UK steel measure for three years, transparent administration, advance consultation before changes — tabled in response to EU tranche movement and as part of the package | Indicative, explicitly non-binding compensation hierarchy tabled for technical-level development: certain aluminium lines, certain chemical and fertiliser lines, certain agri-food lines, certain machinery lines — conditional on final tranche and rate | Dispute restraint counter-offer: UK will not initiate or join a dispute concerning this measure while it operates as agreed, as part of the final package and contingent on mutual performance; 'encourage or coordinate' formulation rejected | Melt-and-pour and anti-circumvention disciplines acceptable only on standard certification and existing customs data, automatic or near-automatic licensing, monitored quota-fill with reallocation of unused tranche capacity | FTA disapplication outside the tranche must fall within the scope of the year-three review with a presumption of remedy | UK signals flexibility on total pool size if the UK tranche reaches a defensible level, given the legal lock | O7: 3800
A8: accommodating__rep1__2026-08-27T16-31-01-925Z | B8: accommodating | C8: 1 | D8: 41 | E8: 4 | F8: eu-geneva | G8: counter | H8: 1100000 | I8: 750000 | J8: country_specific | K8: 35 | L8: 6 | M8: =TRUE() -> TRUE | N8: FINAL PACKAGE — integrated, no further rounds | Conditional closing upgrade: UK tranche rises to 800,000 tonnes with pool held at 1,000,000 (~80% locked UK share) only upon same-round UK acceptance of the full package (35% rate, restraint commitment, steel-measure standstill) | UK tranche locked in legal text: no dilution or reallocation by separate Turkey/Korea/India/Japan Article XXVIII processes | Licence administration on recent-reference basis; melt-and-pour and anti-circumvention via standard certification, automatic licensing, monitored quota-fill, reallocation of unused capacity | Year-three review may recommend volume/rate adjustments on objective pre-defined triggers (import surge relative to domestic demand; capacity utilisation below agreed threshold), subject to mutual agreement, single exercise; cap raised from 15% to 20% with review of the cap at year five — traded specifically for UK acceptance of 35% rate | TCA preferences preserved for UK-originating steel within the UK tranche; all UK preferential access counts within the tranche; no separate FTA pool | FTA disapplication remains in force outside the tranche; its operation enters the year-three review with a presumption that demonstrated injury will be remedied, remedies flowing through the same trigger/mutual-agreement/cap architecture; removal not conceded | UK restraint commitment accepted in UK's formulation: UK will not initiate or join a dispute concerning this measure while it operates as agreed, contingent on mutual performance; 'encourage or coordinate' dropped | UK steel-measure standstill: no worsening of EU country-specific access for three years, transparent administration, advance consultation before changes | Technical-level engagement on UK compensation hierarchy (aluminium, chemicals/fertilisers, agri-food, machinery); no line commitments or valuations; all subject to Trade Policy Committee consultation | O8: 3887
A9: accommodating__rep1__2026-08-27T16-31-01-925Z | B9: accommodating | C9: 1 | D9: 42 | E9: 4 | F9: uk-geneva | G9: counter | H9: 1200000 | I9: 1150000 | J9: country_specific | K9: 25 | L9: 6 | M9: =TRUE() -> TRUE | N9: UK tranche locked in legal text against dilution or reallocation by the EU's separate Article XXVIII processes with Turkey, Korea, India and Japan | Licence-administered on a recent-reference basis; automatic or near-automatic licensing; quota-fill monitored with unused tranche capacity reallocated | TCA preferences for UK-originating steel preserved across the full UK tranche; all preferential access counting within the tranche | Year-three review able to adjust volumes and rates on objective pre-defined triggers: import surge relative to the three-year reference average, and capacity utilisation threshold set so current depressed market conditions can qualify; cap of +/-20%; adjustments by mutual agreement | FTA disapplication outside the tranche within scope of the year-three review with a presumption of remedy for demonstrated injury to UK-originating trade | Melt-and-pour and anti-circumvention disciplines based on standard certification and existing customs data only - verification, not volume restriction | Compensation schedule developed at technical level with concrete valuations across aluminium, chemicals and fertilisers, agri-food and machinery lines, with priority to industrial goods lines of UK export interest | UK restraint commitment as drafted: the UK will not initiate or join a dispute concerning this measure while it operates as agreed, contingent on mutual performance | UK steel measure: no worsening of EU country-specific access for three years, transparent administration, advance consultation before changes | O9: 2652
A10: accommodating__rep2__2026-08-27T21-04-27-460Z | B10: accommodating | C10: 2 | D10: 5 | E10: 1 | F10: eu-geneva | G10: opening | H10: 400000 | I10: 250000 | J10: country_specific | K10: 50 | L10: 4 | M10: =TRUE() -> TRUE | N10: UK tranche administered by licensing rather than first-come first-served | Open to product-line carve-outs within the 41 tariff lines | Open to compensation concessions on other lines in the EU schedule | Review clause timing and scope to be designed jointly | O10: 1359
A11: accommodating__rep2__2026-08-27T21-04-27-460Z | B11: accommodating | C11: 2 | D11: 6 | E11: 1 | F11: uk-geneva | G11: counter | H11: 3000000 | I11: 2200000 | J11: country_specific | K11: 25 | L11: 5 | M11: =TRUE() -> TRUE | N11: Licence-based administration of the TRQ (accepted as basis) | Removal of the provision disapplying FTA tariff reductions for UK-origin steel | Product-line carve-outs to be defined using UK product-level trade data, focused on specialised low-volume lines | Linkage to treatment of EU exporters under the UK's own steel measure, preserving their country-specific quota allocations | O11: 2160
A12: accommodating__rep2__2026-08-27T21-04-27-460Z | B12: accommodating | C12: 2 | D12: 16 | E12: 2 | F12: eu-geneva | G12: counter | H12: 600000 | I12: 400000 | J12: country_specific | K12: 50 | L12: 5 | M12: =TRUE() -> TRUE | N12: Licence-based administration (agreed architecture) | Joint technical exercise on product-level data to identify specialised low-volume UK lines for carve-out, additional to and not counted against the UK tranche | FTA disapplication question reserved for endgame discussion within the overall package | Further EU volume movement expressly conditioned on UK movement on the out-of-quota rate and binding reciprocal certainty for EU exporters under the UK steel measure at or above current country-specific allocation levels | O12: 2753
A13: accommodating__rep2__2026-08-27T21-04-27-460Z | B13: accommodating | C13: 2 | D13: 17 | E13: 2 | F13: uk-geneva | G13: counter | H13: 2200000 | I13: 1700000 | J13: country_specific | K13: 25 | L13: 5 | M13: =TRUE() -> TRUE | N13: Removal of the FTA disapplication provision as it applies to the UK — stated as a package-critical requirement, not a negotiating chip | Product-level trade data tabled; joint technical exercise on carve-outs to begin immediately, with agreed specialised low-volume lines treated as additional access outside the tranche | Review clause to include scope for upward expansion of the tranche on defined triggers | Exploratory (non-binding) discussion invited on treatment of EU exporters under the UK steel measure, contingent on substantial further EU movement on tranche volume | Request for concrete EU proposals on compensation elsewhere in the EU schedule | O13: 2753
... A33: control__rep2__2026-08-27T22-01-39-785Z | B33: control | C33: 2 | D33: 39 | E33: 4 | F33: uk-geneva | G33: counter | H33: 3500000 | I33: 2000000 | J33: country_specific | K33: 20 | L33: 5 | M33: =TRUE() -> TRUE | N33: Complete withdrawal of the FTA-disapplication provision as it applies to UK-originating steel in the concluded text — as confirmed by the EU this round | Country-specific allocation by licence: quarterly windows, rollover of unused quarterly allocations, newcomer reserve, melt-and-pour enforcement — agreed in principle and banked | Product carve-outs for hot-rolled coil feeding downstream processing — banked | Five-year duration with hybrid binding review: objective, quantified, symmetric triggers within pre-agreed bands, obligation to adjust volumes when triggers are met, import penetration and capacity utilisation indicators alongside utilisation and trade-flow triggers — closed subject to drafting | Written UK commitments: preservation of existing EU country-specific quota allocations under the UK steel measure, with a minimum preservation period and a defined consultation procedure with timelines before any tightening — contingent on conclusion, coordinated with the UK's own Article XXVIII process | Compensation envelope on EU industrial tariff lines to be named line-by-line in this session and retained in the concluded package as part of Article XXVIII equivalence | Package tabled as non-extendable and available only for immediate conclusion this session | O33: 2464
A34: firm__rep1__2026-08-27T15-37-34-744Z | B34: firm | C34: 1 | D34: 5 | E34: 1 | F34: eu-geneva | G34: opening | H34: 400000 | J34: global | K34: 50 | M34: =FALSE() -> FALSE | N34: 41 tariff lines: hot-rolled coil, plate, rebar and wire rod as notified | zero-duty access only within the global TRQ; above-quota imports dutiable at the modified bound rate | FTA tariff reductions disapplied for non-EEA partners, including UK-originating steel, consistent with the notified legal text | EEA treatment remains outside this proposal | compensation to be discussed on other EU schedule lines on the basis of substantially equivalent value and verified trade data | administration, licensing, enforcement and anti-circumvention provisions may be discussed without prejudice to the notified architecture | EU seeks conclusion in time for the June Council timetable | O34: 981
A35: firm__rep1__2026-08-27T15-37-34-744Z | B35: firm | C35: 1 | D35: 6 | E35: 1 | F35: uk-geneva | G35: opening | H35: 5000000 | I35: 2400000 | J35: country_specific | K35: 10 | L35: 5 | M35: =TRUE() -> TRUE | N35: In-quota duty remains zero and quotas are administered by licensing with quarterly sub-periods, carryover of unused quarterly volume, and no first-come first-served erosion. | UK tranche based on average 2023-2025 exports by tariff line, with line-level carve-outs where EU evidence does not show UK contribution to injurious overcapacity. | No legal text disapplying EU-UK TCA or other FTA tariff reductions for UK-originating steel; Article XXVIII compensation is additional to, not subtracted from, FTA treatment. | Anti-circumvention and enforcement based on objective melt-and-pour/origin evidence, consultation before measures, and no UK-specific presumptions. | If final UK zero-duty access falls below the representative-period level, automatic compensation through tariff reductions on other EU schedule lines of substantially equivalent value. | Parallel understanding on stable, country-specific treatment of EU exporters under the UK steel measure, without prejudice to the UK's separate Article XXVIII process. | O35: 1450
A36: firm__rep1__2026-08-27T15-37-34-744Z | B36: firm | C36: 1 | D36: 17 | E36: 2 | F36: eu-geneva | G36: counter | H36: 400000 | J36: global | K36: 50 | M36: =FALSE() -> FALSE | N36: No EU movement on total volume, UK-specific tranche, out-of-quota rate, duration, review clause, carve-outs or FTA/TCA treatment this round. | Prepared to discuss licensing-based administration within a global pool as an alternative to first-come first-served, using objective criteria and a representative reference period; no commitment. | Prepared to negotiate robust melt-and-pour enforcement and anti-circumvention provisions applied even-handedly. | UK to provide line-by-line trade data, justification for any product carve-outs, and specific compensation requests on other EU lines before further EU movement. | Probe, without commitment, what the UK would trade for any change in FTA/TCA treatment and what it means by predictable treatment of EU exporters under the UK steel measure, including continuation of EU country-specific quota allocations at current volumes and duration. | O36: 1733
A37: firm__rep1__2026-08-27T15-37-34-744Z | B37: firm | C37: 1 | D37: 18 | E37: 2 | F37: uk-geneva | G37: counter | H37: 5000000 | I37: 2400000 | J37: country_specific | K37: 10 | L37: 5 | M37: =TRUE() -> TRUE | N37: UK tranche administered by import licensing against a representative recent reference period, not first-come first-served | Product-line carve-outs where overcapacity evidence does not justify inclusion, beginning with plate | Full withdrawal of the proposed disapplication of EU-UK TCA and other FTA tariff reductions | Melt-and-pour enforcement and anti-circumvention provisions applied even-handedly to all origins | Compensation on other lines in the EU schedule for any residual gap against the substantially-equivalent test | Parallel, conditional discussion of continued country-specific allocations for EU exporters under the UK steel measure - no figures tabled | O37: 2417
A38: firm__rep1__2026-08-27T15-37-34-744Z | B38: firm | C38: 1 | D38: 28 | E38: 3 | F38: eu-geneva | G38: counter | H38: 1200000 | I38: 600000 | J38: country_specific | K38: 50 | L38: 5 | M38: =TRUE() -> TRUE | N38: Licensing-based administration against a representative recent reference period, replacing first-come first-served | Country-specific reserves for principal supplying interests only — not a general FTA pool | Melt-and-pour enforcement and anti-circumvention provisions applied even-handedly | Technical evidence-based review of plate lines for possible narrow carve-outs | Withdrawal of FTA/TCA disapplication conceivable only as part of a final package delivering: quantified continuation of EU country-specific allocations under the UK steel measure at current volumes for the same duration; UK confirmation it will not join coordinated FTA countermeasures or withdraw concessions if the package is accepted | Substantial equivalence assessed on the whole final package, including residual TRQ access, administration, compensation elsewhere in the schedule, duration/review and parallel treatment | UK to provide remaining line-by-line data, specific other-line compensation requests, and concrete parallel-track figures before Round 4 | O38: 2510
A39: firm__rep1__2026-08-27T15-37-34-744Z | B39: firm | C39: 1 | D39: 29 | E39: 3 | F39: uk-geneva | G39: counter | H39: 5000000 | I39: 2400000 | J39: country_specific | K39: 10 | L39: 5 | M39: =TRUE() -> TRUE | N39: Licensed administration against most recent representative three-year reference period taken as agreed in principle and closed as a topic | Country-specific UK tranche within the total pool | Compensation on other EU lines (motor vehicles and components, chemicals and pharmaceuticals, processed agrifood), quantified against the residual access gap and additive to, not substitutive of, the tranche | Full withdrawal of the TCA/FTA disapplication provision - not priced against a below-representative UK reserve | Technical carve-out review for plate lines, building on data supplied | Even-handed melt-and-pour enforcement and anti-circumvention provisions | Parallel-track offer in shape only: continuation of EU country-specific allocations under the UK steel measure, duration and review to be agreed, tonnage figures strictly conditional on a credible licensed UK tranche and full TCA withdrawal | No UK pre-commitment to forswear Article XXVIII rights; a substantially equivalent package removes the premise for withdrawal of concessions | O39: 3477
A40: firm__rep1__2026-08-27T15-37-34-744Z | B40: firm | C40: 1 | D40: 40 | E40: 4 | F40: eu-geneva | G40: counter | H40: 2000000 | I40: 1200000 | J40: country_specific | K40: 25 | L40: 5 | M40: =TRUE() -> TRUE | N40: Licensed administration against the most recent representative three-year reference period | Country-specific reserves for principal supplying interests only; no general FTA pool | Narrow evidence-based carve-outs on plate lines supported by UK data | Withdrawal of the FTA/TCA disapplication provision as part of the whole package, folded into substantial equivalence | Narrow technical compensation on selected chemicals and pharmaceuticals lines only; nothing on motor vehicles or processed agrifood | Even-handed melt-and-pour enforcement and anti-circumvention provisions | Condition: quantified continuation of EU country-specific allocations under the UK steel measure at current volumes for five years, equivalent review treatment, and a restoration-or-compensation mechanism if the UK amends its measure | Condition: UK confirmation that acceptance fully and finally settles this modification - no withdrawal of concessions, no countermeasures, no participation in coordinated FTA-partner actions in respect of it | Package available this round only; single indivisible whole | O40: 3179
A41: firm__rep1__2026-08-27T15-37-34-744Z | B41: firm | C41: 1 | D41: 41 | E41: 4 | F41: uk-geneva | G41: counter | H41: 3000000 | I41: 2000000 | J41: country_specific | K41: 15 | L41: 5 | M41: =TRUE() -> TRUE | N41: Licensed administration against most recent representative three-year reference period - banked and closed | Full and unconditional withdrawal of the FTA/TCA disapplication provision within the package; not priced against the reserve level | Evidence-based carve-outs on plate lines confirmed | Even-handed melt-and-pour enforcement and anti-circumvention | Compensation list (motor vehicles and components, chemicals and pharmaceuticals, processed agrifood) retained as additive to the tranche | Safeguard element: continuation of EU country-specific allocations under the UK steel measure at current volumes, matching duration, symmetric review, restoration-or-compensation mechanism - strictly conditional and concurrent, inoperative unless the whole package lands | Settlement confirmation limited to the substantially-equivalent formulation: reserved Article XXVIII rights fall away because the package is substantially equivalent; no priced renunciation of WTO rights | Indivisible final offer, expiring at close of round | O41: 4930
A42: firm__rep2__2026-08-27T19-59-32-132Z | B42: firm | C42: 2 | D42: 5 | E42: 1 | F42: eu-geneva | G42: opening | H42: 400000 | J42: global | K42: 50 | M42: =FALSE() -> FALSE | N42: FTA tariff preferences disapplied for all non-EEA FTA partners, including the UK | Open to discussing quota administration (licensing vs first-come first-served) | Open to discussing product-line-specific treatment and compensation on other lines in the EU schedule | Open to discussing duration and review | O42: 1192
A43: firm__rep2__2026-08-27T19-59-32-132Z | B43: firm | C43: 2 | D43: 6 | E43: 1 | F43: uk-geneva | G43: opening | H43: 2500000 | I43: 2200000 | J43: country_specific | K43: 25 | L43: 5 | M43: =TRUE() -> TRUE | N43: Quota administered by licensing, not first-come first-served | No disapplication of FTA/TCA preferential rates for UK-origin steel | Carve-outs from the modification for product lines where UK supply is critical to EU downstream users | Compensation on other lines in the EU schedule in addition to quota terms | Linkage to treatment of EU exporters under the UK steel measure to be addressed as part of overall settlement | O43: 2617
A44: firm__rep2__2026-08-27T19-59-32-132Z | B44: firm | C44: 2 | D44: 18 | E44: 2 | F44: eu-geneva | G44: counter | H44: 400000 | J44: global | K44: 50 | M44: =TRUE() -> TRUE | N44: Quota administered by licensing rather than first-come first-served | Openness to a defined duration with a review point as part of a complete package | Compensation on other EU schedule lines to be tabled in Round 3 | FTA disapplication restated as integral and uniform for non-EEA partners | UK invited to specify concrete reciprocal treatment for EU exporters under the UK steel measure | O44: 2562
A45: firm__rep2__2026-08-27T19-59-32-132Z | B45: firm | C45: 2 | D45: 19 | E45: 2 | F45: uk-geneva | G45: counter | H45: 2500000 | I45: 2200000 | J45: country_specific | K45: 25 | L45: 4 | M45: =TRUE() -> TRUE | N45: Licensing administration of the quota (registering the EU's movement from first-come first-served) | Compensation on other EU schedule lines — first UK indicative list tabled (automotive components, chemicals, agrifood) — additive to quota volume, never a substitute for it | FTA disapplication provision severed from the measure; UK legal position on TCA obligations unchanged | Product carve-outs reserved for discussion only where they protect lines produced by surviving UK plants | Treatment of EU exporters under the UK steel measure discussable only as part of an overall settlement; no volumes or coverage tabled at this stage | O45: 3248
A46: firm__rep2__2026-08-27T19-59-32-132Z | B46: firm | C46: 2 | D46: 30 | E46: 3 | F46: eu-geneva | G46: counter | H46: 400000 | J46: global | K46: 50 | L46: 8 | M46: =TRUE() -> TRUE | N46: Licensing administration (conceded Round 2) — EU proposes both sides exchange valuations of their respective compensation lists before Round 4 | EU compensation list tabled: selected automotive component, chemicals and agrifood lines, additive to quota outcome, not substitutive | Ad referendum signal, no volume attached: a country-specific allocation is not excluded within a complete and reciprocal package reflecting EU-UK market integration under the TCA — expressly conditional on concrete UK specificity (volumes, product coverage, duration, administration) on EU exporter access under the UK steel measure | Duration 8-10 years with mid-term review; UK's 4-year proposal rejected as too short | UK 25% out-of-quota rate demand rejected as outside any operable zone | FTA disapplication provision restated as integral and uniform; not open for discussion at the table | O46: 2813
A47: firm__rep2__2026-08-27T19-59-32-132Z | B47: firm | C47: 2 | D47: 31 | E47: 3 | F47: uk-geneva | G47: counter | H47: 2500000 | I47: 2200000 | J47: country_specific | K47: 25 | L47: 4 | M47: =TRUE() -> TRUE | N47: Licensing administration (as conceded by EU) | Compensation on other EU schedule lines, additive to quota volume, valued on three-year average trade flows at current unit values | Reciprocal security of country-specific access in both markets accepted in principle as settlement frame | Conditional offer: duration-matched guarantee of EU country-specific allocations under the UK steel measure, with improved allocations of the order of several hundred thousand tonnes on agreed lines, gated on a concrete EU tranche figure bearing a serious relationship to actual trade and an out-of-quota rate at or below 25% | Total pool size conceded as secondary if a ring-fenced UK tranche at serious volume is agreed | Product carve-outs welcome where they fully exclude lines produced by surviving UK plants; specific lists referred to capital | FTA disapplication objection reserved on the record; treatment shaped by overall package | Duration signalled as flexible within a package that delivers on volume and rate | Procedural proposal for Round 4: simultaneous exchange of EU tranche figure/rate/duration against precise UK safeguard volumes/coverage/administration | O47: 4489
A48: firm__rep2__2026-08-27T19-59-32-132Z | B48: firm | C48: 2 | D48: 41 | E48: 4 | F48: eu-geneva | G48: counter | H48: 1400000 | I48: 800000 | J48: country_specific | K48: 45 | L48: 8 | M48: =TRUE() -> TRUE | N48: Architecture: 800,000t ring-fenced UK country-specific tranche at zero duty, plus 600,000t global residual pool for all other origins (total circa 1.4mt) | UK tranche framed expressly as reflecting EU-UK market integration under the TCA — framing integral to the offer | Licensing administration throughout (no first-come first-served) | Mid-term review within the 8-year duration | Compensation list as tabled (automotive components, chemicals, agrifood), additive, valued on shared method of three-year average trade flows at current unit values | Openness to full carve-out of limited sub-lines where UK production concentrated (plate and rebar sub-lines indicated), to be shaped within the session | CONDITION 1: simultaneous tabling of precise guaranteed EU country-specific allocations under the UK steel measure — volumes, coverage, administration — matched to full duration; tranche scales down proportionately if reciprocal volumes disappoint | CONDITION 2: explicit UK commitment to disengage from any coordinated FTA dispute action with Japan and Korea in relation to this measure | FTA preference disapplication provision position unchanged | O48: 3422
A49: firm__rep2__2026-08-27T19-59-32-132Z | B49: firm | C49: 2 | D49: 43 | E49: 4 | F49: uk-geneva | G49: counter | H49: 2100000 | I49: 1500000 | J49: country_specific | K49: 30 | L49: 8 | M49: =TRUE() -> TRUE | N49: UK tranche ring-fenced and licensing-administered; residual global pool of 600,000 tonnes not contested | Full exclusion (zero bound restored) of plate and rebar sub-lines produced by surviving UK plants, credited tonne-for-tonne at three-year average export volumes as effective access additional to the tranche | Binding mid-term review no later than year 4 | Reciprocal: duration-matched guarantee of existing EU country-specific allocations under the UK steel measure plus improvements of up to 200,000 tonnes on agreed lines, rising toward 300,000 tonnes if effective access reaches 1.6-1.8 million tonnes; administration mirrored (licensing, duration-matched) | Compensation lists on other schedule lines valued on three-year average trade flows at current unit values, additive to quota volume, never a substitute | No commitment on dispute action with other members can be given at the table; a satisfactory overall package shapes UK consideration of adjacent matters | FTA preference provision: UK legal objection remains on the record | O49: 5053
A50: focal_firm_ukgva__rep1__2026-08-27T18-37-08-506Z | B50: focal_firm_ukgva | C50: 1 | D50: 5 | E50: 1 | F50: eu-geneva | G50: opening | H50: 400000 | J50: global | K50: 50 | M50: =FALSE() -> FALSE | N50: Notified FTA preference disapplication remains part of the package, but its application to UK-origin steel is explicitly open to negotiation within this process | All design parameters (volume, allocation, administration, duration, review, product coverage) stated as open for discussion | Compensation on other lines in the EU schedule available for discussion | Proposal to address the EU and UK steel measures in parallel, with reciprocal treatment of exporters as an organising principle | O50: 2073
A51: focal_firm_ukgva__rep1__2026-08-27T18-37-08-506Z | B51: focal_firm_ukgva | C51: 1 | D51: 6 | E51: 1 | F51: uk-geneva | G51: opening | H51: 3000000 | I51: 2400000 | J51: country_specific | K51: 15 | L51: 3 | M51: =TRUE() -> TRUE | N51: Withdrawal of the proposed disapplication of FTA/TCA tariff reductions for UK-originating steel | Licensed administration with quarterly release and carryover of unused tranche tonnage | Carve-out of tariff lines where UK is the dominant supplier and EU domestic production is minimal, list to be tabled | Compensation on other lines in the EU schedule to be registered, pending the EU's response on volume and allocation | Reciprocal predictability for EU exporters under the UK steel measure to be addressed in parallel, contingent on overall balance | O51: 2849
A52: focal_firm_ukgva__rep1__2026-08-27T18-37-08-506Z | B52: focal_firm_ukgva | C52: 1 | D52: 17 | E52: 2 | F52: eu-geneva | G52: counter | H52: 1100000 | I52: 900000 | J52: country_specific | K52: 30 | L52: 5 | M52: =TRUE() -> TRUE | N52: Administration by import licensing with quarterly release | Carryover of unused quarterly tonnage, capped at one quarter | Mandatory mid-term review (year 3) covering volumes, allocation and out-of-quota rate | EU prepared to revisit scope of FTA-disapplication clause as part of overall settlement, including preserving TCA preference operation within the UK tranche — movement conditional on UK movement on volume/rate | Informal parallel discussion of UK safeguard measure: EU expects preservation of EU country-specific allocations at current volumes, no shift to global FCFS | UK invited to table product carve-out list for examination; no commitments made | UK tranche sized with regard to other members' Article XXVIII reservations (Turkey, Korea, India, Japan) | O52: 4267
A53: focal_firm_ukgva__rep1__2026-08-27T18-37-08-506Z | B53: focal_firm_ukgva | C53: 1 | D53: 18 | E53: 2 | F53: uk-geneva | G53: counter | H53: 3000000 | I53: 2400000 | J53: country_specific | K53: 15 | L53: 3 | M53: =TRUE() -> TRUE | N53: Import licensing with quarterly release and carryover of unused tonnage (one-quarter cap workable) | Withdrawal — not narrowing — of the clause disapplying FTA tariff reductions for UK-originating steel; UK reserves all TCA rights | Carve-out list of lines where UK supply is dominant and EU domestic production minimal to be tabled this week | In-principle, non-quantified linkage: preservation of EU country-specific allocations under the UK steel measure contingent on UK tranche near representative volumes and withdrawal of FTA disapplication | Openness to a longer duration only if the review clause carries a defined obligation to recalibrate volumes against actual trade | O53: 3563
A54: focal_firm_ukgva__rep1__2026-08-27T18-37-08-506Z | B54: focal_firm_ukgva | C54: 1 | D54: 29 | E54: 3 | F54: eu-geneva | G54: counter | H54: 1300000 | I54: 1150000 | J54: country_specific | K54: 28 | L54: 5 | M54: =TRUE() -> TRUE | N54: Licensing administration with quarterly release | Carryover of unused tonnage capped at one quarter | Binding mid-term review with defined obligation to recalibrate quota volumes against trade-flow and overcapacity data, presumption of adjustment, symmetric design, no automatic tonnage entitlements | Full withdrawal of FTA-disapplication clause available as part of package, conditional on tranche ≤1.2Mt, OQR ≥25%, and locked-in safeguard understanding | Mutual understanding (exchange of letters) preserving EU country-specific allocations under UK steel measure at current volumes, no shift to FCFS | UK carve-out list to be examined as endgame element | O54: 4059
A55: focal_firm_ukgva__rep1__2026-08-27T18-37-08-506Z | B55: focal_firm_ukgva | C55: 1 | D55: 30 | E55: 3 | F55: uk-geneva | G55: counter | H55: 3000000 | I55: 2400000 | J55: country_specific | K55: 15 | L55: 5 | M55: =TRUE() -> TRUE | N55: Binding mid-term review recalibrating quota volumes, allocation and out-of-quota rate against actual trade flows and overcapacity data, symmetric in design with presumption of adjustment | Import licensing with quarterly release; carryover of unused tonnage capped at one quarter | Full withdrawal of the FTA disapplication clause as a required element of any settlement | UK carve-out list tabled with representative-period trade data; treatment as core endgame element | In-principle confirmation of preservation of existing EU country-specific allocations under the UK safeguard measure, matching duration and review, contingent on withdrawal of the clause and a UK tranche approaching representative-period volumes | Conditional signal: London could engage on the volume figure within a package including clause withdrawal, out-of-quota rate meaningfully below 30%, and progress on carve-outs | O55: 3006
A56: focal_firm_ukgva__rep1__2026-08-27T18-37-08-506Z | B56: focal_firm_ukgva | C56: 1 | D56: 40 | E56: 4 | F56: eu-geneva | G56: counter | H56: 1500000 | I56: 1350000 | J56: country_specific | K56: 25 | L56: 5 | M56: =TRUE() -> TRUE | N56: Final, indivisible package: all elements conditional on acceptance of the whole this round | Full withdrawal of FTA-disapplication clause, extended to all FTA partners (EEA excepted as notified) | Carve-outs accepted for lines where UK supply dominant and EU production minimal/nil, capped at 250,000t representative-period trade; overflow lines receive guaranteed residual-pool shares | Import licensing administration with quarterly release; carryover of unused tonnage capped at one quarter | Binding mid-term recalibration against actual trade flows and overcapacity data, symmetric, presumption of adjustment, no automatic tonnage entitlements | Exchange of letters: preservation of EU country-specific allocations under UK steel measure at current volumes, matching five-year duration and review, no shift to FCFS | One to two pre-cleared compensation lines elsewhere in EU schedule available if needed to close | Reserve headroom (tranche to 1.4Mt, OQR to 22%) held for closing concessions against UK acceptance only | O56: 3986
A57: focal_firm_ukgva__rep1__2026-08-27T18-37-08-506Z | B57: focal_firm_ukgva | C57: 1 | D57: 41 | E57: 4 | F57: uk-geneva | G57: counter | H57: 2000000 | I57: 1800000 | J57: country_specific | K57: 20 | L57: 5 | M57: =TRUE() -> TRUE | N57: Binding criteria-based mid-term recalibration against actual trade flows and overcapacity data, symmetric with presumption of adjustment, as described by the EU in Round 3 | Full withdrawal of the FTA disapplication clause, extended to all FTA partners, as tabled by the EU | Carve-outs per the UK list at or above the EU's 250,000-tonne cap, reverting to zero duty outside the quota, with qualifying lines beyond the cap receiving guaranteed residual pool shares | EU's reserved compensation lines elsewhere in its schedule to be tabled and added to the package this round, per the EU's own offer against a residual gap in substantially equivalent value | Import licensing administration with quarterly release and carryover capped at one quarter | Exchange of letters preserving EU country-specific allocations under the UK steel measure at current volumes, matching duration and review, to be signed simultaneously with conclusion of the main package | UK reserves all Article XXVIII rights pending London's decision on the final terms | O57: 2676
A58: focal_firm_ukgva__rep2__2026-08-27T23-11-30-551Z | B58: focal_firm_ukgva | C58: 2 | D58: 5 | E58: 1 | F58: eu-geneva | G58: opening | H58: 400000 | J58: global | K58: 50 | M58: =FALSE() -> FALSE | N58: First-come, first-served administration | Non-EEA FTA preference disapplication remains part of the EU's notified opening text | Product coverage as notified across the 41 tariff lines | Compensation, enforcement and TCA interface open for discussion | No partial agreement before an overall package is settled | O58: 822
A59: focal_firm_ukgva__rep2__2026-08-27T23-11-30-551Z | B59: focal_firm_ukgva | C59: 2 | D59: 6 | E59: 1 | F59: uk-geneva | G59: counter | H59: 3000000 | I59: 2200000 | J59: country_specific | K59: 10 | L59: 5 | M59: =TRUE() -> TRUE | N59: Quota administered by import licensing, not first-come first-served | Removal of legal text disapplying non-EEA FTA preferences, including TCA preferences for UK-originating steel | Carve-outs for specific product lines where EU downstream manufacturers depend on UK supply | Treatment of EU exporters under the UK's parallel steel measure to be discussed only as part of the overall package | Enforcement and anti-circumvention provisions to be agreed mutually, covering transhipment and minor processing | O59: 1576
...
