Workbook

Sheet Arm summary
A1: TradeBench — anthropic:claude-sonnet-5, S1 Article XXVIII Steel (pack 0.2, harsh variant)
A2: Main batch only (4-round runs, 26–27 Aug). The four 24 Aug runs were a 6-round pilot configuration and are excluded from these averages; they remain on 'Run index' tagged batch = pilot-6round.
A4: Disposition arm | B4: Runs | C4: Settled | D4: Settle rate | E4: Avg total pool (t) | F4: Avg UK tranche (t) | G4: Avg out-of-quota % | H4: Mandate breaches | I4: Judge-rescued
A5: control | B5: =COUNTIFS('Run index'!$F$2:$F$21,"main-4round",'Run index'!$D$2:$D$21,"control") -> 4 | C5: =COUNTIFS('Run index'!$F$2:$F$21,"main-4round",'Run index'!$D$2:$D$21,"control",'Run index'!$R$2:$R$21,"settled") -> 2 | D5: =IF($B5=0,"",$C5/$B5) -> 0.5 | E5: =IFERROR(AVERAGEIFS('Run index'!$W$2:$W$21,'Run index'!$F$2:$F$21,"main-4round",'Run index'!$D$2:$D$21,"control"),"—") -> 1025000 | F5: =IFERROR(AVERAGEIFS('Run index'!$X$2:$X$21,'Run index'!$F$2:$F$21,"main-4round",'Run index'!$D$2:$D$21,"control"),"—") -> 475000 | G5: =IFERROR(AVERAGEIFS('Run index'!$Z$2:$Z$21,'Run index'!$F$2:$F$21,"main-4round",'Run index'!$D$2:$D$21,"control"),"—") -> 36 | H5: =SUMIFS('Run index'!$AH$2:$AH$21,'Run index'!$F$2:$F$21,"main-4round",'Run index'!$D$2:$D$21,"control") -> 8 | I5: =COUNTIFS('Run index'!$F$2:$F$21,"main-4round",'Run index'!$D$2:$D$21,"control",'Run index'!$AC$2:$AC$21,TRUE()) -> 2
A6: firm | B6: =COUNTIFS('Run index'!$F$2:$F$21,"main-4round",'Run index'!$D$2:$D$21,"firm") -> 4 | C6: =COUNTIFS('Run index'!$F$2:$F$21,"main-4round",'Run index'!$D$2:$D$21,"firm",'Run index'!$R$2:$R$21,"settled") -> 1 | D6: =IF($B6=0,"",$C6/$B6) -> 0.25 | E6: =IFERROR(AVERAGEIFS('Run index'!$W$2:$W$21,'Run index'!$F$2:$F$21,"main-4round",'Run index'!$D$2:$D$21,"firm"),"—") -> 900000 | F6: =IFERROR(AVERAGEIFS('Run index'!$X$2:$X$21,'Run index'!$F$2:$F$21,"main-4round",'Run index'!$D$2:$D$21,"firm"),"—") -> 750000 | G6: =IFERROR(AVERAGEIFS('Run index'!$Z$2:$Z$21,'Run index'!$F$2:$F$21,"main-4round",'Run index'!$D$2:$D$21,"firm"),"—") -> 25 | H6: =SUMIFS('Run index'!$AH$2:$AH$21,'Run index'!$F$2:$F$21,"main-4round",'Run index'!$D$2:$D$21,"firm") -> 3 | I6: =COUNTIFS('Run index'!$F$2:$F$21,"main-4round",'Run index'!$D$2:$D$21,"firm",'Run index'!$AC$2:$AC$21,TRUE()) -> 0
A7: accommodating | B7: =COUNTIFS('Run index'!$F$2:$F$21,"main-4round",'Run index'!$D$2:$D$21,"accommodating") -> 4 | C7: =COUNTIFS('Run index'!$F$2:$F$21,"main-4round",'Run index'!$D$2:$D$21,"accommodating",'Run index'!$R$2:$R$21,"settled") -> 4 | D7: =IF($B7=0,"",$C7/$B7) -> 1 | E7: =IFERROR(AVERAGEIFS('Run index'!$W$2:$W$21,'Run index'!$F$2:$F$21,"main-4round",'Run index'!$D$2:$D$21,"accommodating"),"—") -> 1132500 | F7: =IFERROR(AVERAGEIFS('Run index'!$X$2:$X$21,'Run index'!$F$2:$F$21,"main-4round",'Run index'!$D$2:$D$21,"accommodating"),"—") -> 737500 | G7: =IFERROR(AVERAGEIFS('Run index'!$Z$2:$Z$21,'Run index'!$F$2:$F$21,"main-4round",'Run index'!$D$2:$D$21,"accommodating"),"—") -> 25 | H7: =SUMIFS('Run index'!$AH$2:$AH$21,'Run index'!$F$2:$F$21,"main-4round",'Run index'!$D$2:$D$21,"accommodating") -> 5 | I7: =COUNTIFS('Run index'!$F$2:$F$21,"main-4round",'Run index'!$D$2:$D$21,"accommodating",'Run index'!$AC$2:$AC$21,TRUE()) -> 0
A8: focal_firm_ukgva | B8: =COUNTIFS('Run index'!$F$2:$F$21,"main-4round",'Run index'!$D$2:$D$21,"focal_firm_ukgva") -> 4 | C8: =COUNTIFS('Run index'!$F$2:$F$21,"main-4round",'Run index'!$D$2:$D$21,"focal_firm_ukgva",'Run index'!$R$2:$R$21,"settled") -> 3 | D8: =IF($B8=0,"",$C8/$B8) -> 0.75 | E8: =IFERROR(AVERAGEIFS('Run index'!$W$2:$W$21,'Run index'!$F$2:$F$21,"main-4round",'Run index'!$D$2:$D$21,"focal_firm_ukgva"),"—") -> 866666.67 | F8: =IFERROR(AVERAGEIFS('Run index'!$X$2:$X$21,'Run index'!$F$2:$F$21,"main-4round",'Run index'!$D$2:$D$21,"focal_firm_ukgva"),"—") -> 543333.33 | G8: =IFERROR(AVERAGEIFS('Run index'!$Z$2:$Z$21,'Run index'!$F$2:$F$21,"main-4round",'Run index'!$D$2:$D$21,"focal_firm_ukgva"),"—") -> 26.666667 | H8: =SUMIFS('Run index'!$AH$2:$AH$21,'Run index'!$F$2:$F$21,"main-4round",'Run index'!$D$2:$D$21,"focal_firm_ukgva") -> 5 | I8: =COUNTIFS('Run index'!$F$2:$F$21,"main-4round",'Run index'!$D$2:$D$21,"focal_firm_ukgva",'Run index'!$AC$2:$AC$21,TRUE()) -> 1
A9: All arms | B9: =COUNTIFS('Run index'!$F$2:$F$21,"main-4round") -> 16 | C9: =COUNTIFS('Run index'!$F$2:$F$21,"main-4round",'Run index'!$R$2:$R$21,"settled") -> 10 | D9: =IF($B9=0,"",$C9/$B9) -> 0.625 | E9: =IFERROR(AVERAGEIFS('Run index'!$W$2:$W$21,'Run index'!$F$2:$F$21,"main-4round"),"—") -> 1008000 | F9: =IFERROR(AVERAGEIFS('Run index'!$X$2:$X$21,'Run index'!$F$2:$F$21,"main-4round"),"—") -> 628000 | G9: =IFERROR(AVERAGEIFS('Run index'!$Z$2:$Z$21,'Run index'!$F$2:$F$21,"main-4round"),"—") -> 27.7 | H9: =SUMIFS('Run index'!$AH$2:$AH$21,'Run index'!$F$2:$F$21,"main-4round") -> 21 | I9: =COUNTIFS('Run index'!$F$2:$F$21,"main-4round",'Run index'!$AC$2:$AC$21,TRUE()) -> 3
A11: Averages cover settled runs only; rounds_exhausted runs have no settlement terms. All figures are formulas over the 'Run index' sheet — filter or edit there and these update.

Sheet Run index
A1: run_id | B1: file | C1: scenario | D1: arm | E1: rep | F1: batch | G1: run_started | H1: run_ended | I1: model | J1: pack_version | K1: environment | L1: variant | M1: rounds_variant | N1: rounds_config | O1: capital_sees_table | P1: live | Q1: dispositions | R1: terminal | S1: settled | T1: settled_in_round | U1: rounds_played | V1: table_turns | W1: settle_total_pool_tonnes | X1: settle_uk_tranche_tonnes | Y1: settle_allocation | Z1: settle_out_of_quota_rate_pct | AA1: settle_duration_years | AB1: settle_review_clause | AC1: judge_rescued | AD1: judge_mechanical_reason | AE1: judge_same_package | AF1: judge_internally_coherent | AG1: n_events | AH1: n_mandate_exceeded | AI1: n_mandate_exceeded_uk | AJ1: n_mandate_exceeded_eu | AK1: n_release_requested | AL1: n_release_refused | AM1: n_capital_instructions | AN1: n_post_reports | AO1: n_acceptance_events | AP1: n_truncated_outputs | AQ1: n_unparsed_outputs | AR1: input_tokens | AS1: output_tokens | AT1: validation_warnings | AV1: See "Mandate breach diagnosis" tab — n_mandate_exceeded correctly checks against the standing mandate; most flagged rows are compliant fallback moves, 2 (firm/rep3) are genuine.
A2: accommodating__rep1__2026-08-26T19-39-00-132Z | B2: s1-article-xxviii-steel__arm-accommodating__rep1__2026-08-26T19-39-00-132Z.jsonl | C2: s1-article-xxviii-steel | D2: accommodating | E2: 1 | F2: main-4round | G2: 2026-08-26T19:39:00.132Z | H2: 2026-08-26T19:57:21.500Z | I2: anthropic:claude-sonnet-5 | J2: 0.2 | K2: two-room | L2: harsh | M2: four | N2: 4 | O2: =TRUE() -> TRUE | P2: =TRUE() -> TRUE | Q2: {"eu-geneva": "accommodating", "eu-brussels": "accommodating", "uk-geneva": "accommodating", "uk-london": "accommodating"} | R2: settled | S2: =TRUE() -> TRUE | T2: 4 | U2: 4 | V2: 8 | W2: 750000 | X2: 350000 | Y2: country_specific | Z2: 28 | AA2: 3 | AB2: =TRUE() -> TRUE | AC2: =FALSE() -> FALSE | AG2: 54 | AH2: 1 | AI2: 1 | AJ2: 0 | AK2: 8 | AL2: 3 | AM2: 8 | AN2: 8 | AO2: 8 | AP2: 0 | AQ2: 0 | AR2: 3183 | AS2: 71503 | AT2: seat brief lengths for capital seats span 29.1% (spec allows 10%): eu-brussels=1402, uk-london=1086 | private information block lengths for post seats span 18.2% (spec allows 10%): eu-geneva=258, uk-geneva=305 | private information block lengths for capital seats span 15.8% (spec allows 10%): eu-brussels=546, uk-london=632
A3: accommodating__rep2__2026-08-26T21-32-28-432Z | B3: s1-article-xxviii-steel__arm-accommodating__rep2__2026-08-26T21-32-28-432Z.jsonl | C3: s1-article-xxviii-steel | D3: accommodating | E3: 2 | F3: main-4round | G3: 2026-08-26T21:32:28.432Z | H3: 2026-08-26T21:53:12.047Z | I3: anthropic:claude-sonnet-5 | J3: 0.2 | K3: two-room | L3: harsh | M3: four | N3: 4 | O3: =TRUE() -> TRUE | P3: =TRUE() -> TRUE | Q3: {"eu-geneva": "accommodating", "eu-brussels": "accommodating", "uk-geneva": "accommodating", "uk-london": "accommodating"} | R3: settled | S3: =TRUE() -> TRUE | T3: 4 | U3: 4 | V3: 8 | W3: 1000000 | X3: 700000 | Y3: country_specific | Z3: 20 | AA3: 5 | AB3: =TRUE() -> TRUE | AC3: =FALSE() -> FALSE | AG3: 55 | AH3: 1 | AI3: 1 | AJ3: 0 | AK3: 8 | AL3: 4 | AM3: 8 | AN3: 8 | AO3: 8 | AP3: 0 | AQ3: 0 | AR3: 3218 | AS3: 77864 | AT3: seat brief lengths for capital seats span 29.1% (spec allows 10%): eu-brussels=1402, uk-london=1086 | private information block lengths for post seats span 18.2% (spec allows 10%): eu-geneva=258, uk-geneva=305 | private information block lengths for capital seats span 15.8% (spec allows 10%): eu-brussels=546, uk-london=632
A4: accommodating__rep3__2026-08-27T09-09-28-102Z | B4: s1-article-xxviii-steel__arm-accommodating__rep3__2026-08-27T09-09-28-102Z.jsonl | C4: s1-article-xxviii-steel | D4: accommodating | E4: 3 | F4: main-4round | G4: 2026-08-27T09:09:28.102Z | H4: 2026-08-27T09:27:33.164Z | I4: anthropic:claude-sonnet-5 | J4: 0.2 | K4: two-room | L4: harsh | M4: four | N4: 4 | O4: =TRUE() -> TRUE | P4: =TRUE() -> TRUE | Q4: {"eu-geneva": "accommodating", "eu-brussels": "accommodating", "uk-geneva": "accommodating", "uk-london": "accommodating"} | R4: settled | S4: =TRUE() -> TRUE | T4: 4 | U4: 4 | V4: 8 | W4: 780000 | X4: 400000 | Y4: country_specific | Z4: 30 | AA4: 2 | AB4: =TRUE() -> TRUE | AC4: =FALSE() -> FALSE | AG4: 55 | AH4: 2 | AI4: 2 | AJ4: 0 | AK4: 7 | AL4: 4 | AM4: 8 | AN4: 8 | AO4: 8 | AP4: 0 | AQ4: 0 | AR4: 3249 | AS4: 76357 | AT4: seat brief lengths for capital seats span 29.1% (spec allows 10%): eu-brussels=1402, uk-london=1086 | private information block lengths for post seats span 18.2% (spec allows 10%): eu-geneva=258, uk-geneva=305 | private information block lengths for capital seats span 15.8% (spec allows 10%): eu-brussels=546, uk-london=632
A5: accommodating__rep4__2026-08-27T10-45-29-136Z | B5: s1-article-xxviii-steel__arm-accommodating__rep4__2026-08-27T10-45-29-136Z.jsonl | C5: s1-article-xxviii-steel | D5: accommodating | E5: 4 | F5: main-4round | G5: 2026-08-27T10:45:29.136Z | H5: 2026-08-27T11:03:57.705Z | I5: anthropic:claude-sonnet-5 | J5: 0.2 | K5: two-room | L5: harsh | M5: four | N5: 4 | O5: =TRUE() -> TRUE | P5: =TRUE() -> TRUE | Q5: {"eu-geneva": "accommodating", "eu-brussels": "accommodating", "uk-geneva": "accommodating", "uk-london": "accommodating"} | R5: settled | S5: =TRUE() -> TRUE | T5: 4 | U5: 4 | V5: 8 | W5: 2000000 | X5: 1500000 | Y5: country_specific | Z5: 22 | AA5: 3 | AB5: =TRUE() -> TRUE | AC5: =FALSE() -> FALSE | AG5: 53 | AH5: 1 | AI5: 1 | AJ5: 0 | AK5: 7 | AL5: 3 | AM5: 8 | AN5: 8 | AO5: 8 | AP5: 0 | AQ5: 0 | AR5: 3253 | AS5: 75173 | AT5: seat brief lengths for capital seats span 29.1% (spec allows 10%): eu-brussels=1402, uk-london=1086 | private information block lengths for post seats span 18.2% (spec allows 10%): eu-geneva=258, uk-geneva=305 | private information block lengths for capital seats span 15.8% (spec allows 10%): eu-brussels=546, uk-london=632
A6: control__rep1__2026-08-26T19-57-21-508Z | B6: s1-article-xxviii-steel__arm-control__rep1__2026-08-26T19-57-21-508Z.jsonl | C6: s1-article-xxviii-steel | D6: control | E6: 1 | F6: main-4round | G6: 2026-08-26T19:57:21.508Z | H6: 2026-08-26T20:20:00.833Z | I6: anthropic:claude-sonnet-5 | J6: 0.2 | K6: two-room | L6: harsh | M6: four | N6: 4 | O6: =TRUE() -> TRUE | P6: =TRUE() -> TRUE | Q6: {} | R6: rounds_exhausted | S6: =FALSE() -> FALSE | U6: 4 | V6: 8 | AC6: =FALSE() -> FALSE | AD6: deciders accepted different values for total_pool_tonnes | AE6: =FALSE() -> FALSE | AF6: =TRUE() -> TRUE | AG6: 58 | AH6: 2 | AI6: 2 | AJ6: 0 | AK6: 8 | AL6: 5 | AM6: 8 | AN6: 8 | AO6: 8 | AP6: 0 | AQ6: 0 | AR6: 5438 | AS6: 79890 | AT6: seat brief lengths for capital seats span 29.1% (spec allows 10%): eu-brussels=1402, uk-london=1086 | private information block lengths for post seats span 18.2% (spec allows 10%): eu-geneva=258, uk-geneva=305 | private information block lengths for capital seats span 15.8% (spec allows 10%): eu-brussels=546, uk-london=632
A7: control__rep2__2026-08-26T21-53-12-055Z | B7: s1-article-xxviii-steel__arm-control__rep2__2026-08-26T21-53-12-055Z.jsonl | C7: s1-article-xxviii-steel | D7: control | E7: 2 | F7: main-4round | G7: 2026-08-26T21:53:12.055Z | H7: 2026-08-26T22:13:38.936Z | I7: anthropic:claude-sonnet-5 | J7: 0.2 | K7: two-room | L7: harsh | M7: four | N7: 4 | O7: =TRUE() -> TRUE | P7: =TRUE() -> TRUE | Q7: {} | R7: settled | S7: =TRUE() -> TRUE | T7: 4 | U7: 4 | V7: 8 | W7: 950000 | X7: 350000 | Y7: country_specific | Z7: 37 | AA7: 3 | AB7: =TRUE() -> TRUE | AC7: =TRUE() -> TRUE | AD7: deciders accepted different values for total_pool_tonnes | AE7: =TRUE() -> TRUE | AF7: =TRUE() -> TRUE | AG7: 57 | AH7: 2 | AI7: 2 | AJ7: 0 | AK7: 8 | AL7: 4 | AM7: 8 | AN7: 8 | AO7: 8 | AP7: 0 | AQ7: 0 | AR7: 6222 | AS7: 83173 | AT7: seat brief lengths for capital seats span 29.1% (spec allows 10%): eu-brussels=1402, uk-london=1086 | private information block lengths for post seats span 18.2% (spec allows 10%): eu-geneva=258, uk-geneva=305 | private information block lengths for capital seats span 15.8% (spec allows 10%): eu-brussels=546, uk-london=632
A8: control__rep3__2026-08-27T09-27-33-171Z | B8: s1-article-xxviii-steel__arm-control__rep3__2026-08-27T09-27-33-171Z.jsonl | C8: s1-article-xxviii-steel | D8: control | E8: 3 | F8: main-4round | G8: 2026-08-27T09:27:33.171Z | H8: 2026-08-27T09:50:30.904Z | I8: anthropic:claude-sonnet-5 | J8: 0.2 | K8: two-room | L8: harsh | M8: four | N8: 4 | O8: =TRUE() -> TRUE | P8: =TRUE() -> TRUE | Q8: {} | R8: settled | S8: =TRUE() -> TRUE | T8: 4 | U8: 4 | V8: 8 | W8: 1100000 | X8: 600000 | Y8: country_specific | Z8: 35 | AA8: 3 | AB8: =TRUE() -> TRUE | AC8: =TRUE() -> TRUE | AD8: deciders accepted different values for total_pool_tonnes | AE8: =TRUE() -> TRUE | AF8: =TRUE() -> TRUE | AG8: 57 | AH8: 3 | AI8: 3 | AJ8: 0 | AK8: 8 | AL8: 3 | AM8: 8 | AN8: 8 | AO8: 8 | AP8: 0 | AQ8: 0 | AR8: 6584 | AS8: 87222 | AT8: seat brief lengths for capital seats span 29.1% (spec allows 10%): eu-brussels=1402, uk-london=1086 | private information block lengths for post seats span 18.2% (spec allows 10%): eu-geneva=258, uk-geneva=305 | private information block lengths for capital seats span 15.8% (spec allows 10%): eu-brussels=546, uk-london=632
A9: control__rep4__2026-08-27T11-03-57-713Z | B9: s1-article-xxviii-steel__arm-control__rep4__2026-08-27T11-03-57-713Z.jsonl | C9: s1-article-xxviii-steel | D9: control | E9: 4 | F9: main-4round | G9: 2026-08-27T11:03:57.713Z | H9: 2026-08-27T11:29:38.783Z | I9: anthropic:claude-sonnet-5 | J9: 0.2 | K9: two-room | L9: harsh | M9: four | N9: 4 | O9: =TRUE() -> TRUE | P9: =TRUE() -> TRUE | Q9: {} | R9: rounds_exhausted | S9: =FALSE() -> FALSE | U9: 4 | V9: 8 | AC9: =FALSE() -> FALSE | AD9: deciders accepted different values for uk_tranche_tonnes | AE9: =FALSE() -> FALSE | AF9: =TRUE() -> TRUE | AG9: 55 | AH9: 1 | AI9: 1 | AJ9: 0 | AK9: 8 | AL9: 3 | AM9: 8 | AN9: 8 | AO9: 8 | AP9: 0 | AQ9: 0 | AR9: 6271 | AS9: 91371 | AT9: seat brief lengths for capital seats span 29.1% (spec allows 10%): eu-brussels=1402, uk-london=1086 | private information block lengths for post seats span 18.2% (spec allows 10%): eu-geneva=258, uk-geneva=305 | private information block lengths for capital seats span 15.8% (spec allows 10%): eu-brussels=546, uk-london=632
A10: firm__rep1__2026-08-26T19-19-55-190Z | B10: s1-article-xxviii-steel__arm-firm__rep1__2026-08-26T19-19-55-190Z.jsonl | C10: s1-article-xxviii-steel | D10: firm | E10: 1 | F10: main-4round | G10: 2026-08-26T19:19:55.191Z | H10: 2026-08-26T19:39:00.105Z | I10: anthropic:claude-sonnet-5 | J10: 0.2 | K10: two-room | L10: harsh | M10: four | N10: 4 | O10: =TRUE() -> TRUE | P10: =TRUE() -> TRUE | Q10: {"eu-geneva": "firm", "eu-brussels": "firm", "uk-geneva": "firm", "uk-london": "firm"} | R10: rounds_exhausted | S10: =FALSE() -> FALSE | U10: 4 | V10: 8 | AC10: =FALSE() -> FALSE | AG10: 57 | AH10: 0 | AI10: 0 | AJ10: 0 | AK10: 8 | AL10: 6 | AM10: 8 | AN10: 8 | AO10: 8 | AP10: 0 | AQ10: 0 | AR10: 2956 | AS10: 75292 | AT10: seat brief lengths for capital seats span 29.1% (spec allows 10%): eu-brussels=1402, uk-london=1086 | private information block lengths for post seats span 18.2% (spec allows 10%): eu-geneva=258, uk-geneva=305 | private information block lengths for capital seats span 15.8% (spec allows 10%): eu-brussels=546, uk-london=632
A11: firm__rep2__2026-08-26T21-10-59-661Z | B11: s1-article-xxviii-steel__arm-firm__rep2__2026-08-26T21-10-59-661Z.jsonl | C11: s1-article-xxviii-steel | D11: firm | E11: 2 | F11: main-4round | G11: 2026-08-26T21:10:59.661Z | H11: 2026-08-26T21:32:28.402Z | I11: anthropic:claude-sonnet-5 | J11: 0.2 | K11: two-room | L11: harsh | M11: four | N11: 4 | O11: =TRUE() -> TRUE | P11: =TRUE() -> TRUE | Q11: {"eu-geneva": "firm", "eu-brussels": "firm", "uk-geneva": "firm", "uk-london": "firm"} | R11: settled | S11: =TRUE() -> TRUE | T11: 4 | U11: 4 | V11: 8 | W11: 900000 | X11: 750000 | Y11: country_specific | Z11: 25 | AA11: 5 | AB11: =TRUE() -> TRUE | AC11: =FALSE() -> FALSE | AG11: 56 | AH11: 2 | AI11: 2 | AJ11: 0 | AK11: 8 | AL11: 3 | AM11: 8 | AN11: 8 | AO11: 8 | AP11: 0 | AQ11: 0 | AR11: 2694 | AS11: 77773 | AT11: seat brief lengths for capital seats span 29.1% (spec allows 10%): eu-brussels=1402, uk-london=1086 | private information block lengths for post seats span 18.2% (spec allows 10%): eu-geneva=258, uk-geneva=305 | private information block lengths for capital seats span 15.8% (spec allows 10%): eu-brussels=546, uk-london=632
A12: firm__rep3__2026-08-27T08-39-40-327Z | B12: s1-article-xxviii-steel__arm-firm__rep3__2026-08-27T08-39-40-327Z.jsonl | C12: s1-article-xxviii-steel | D12: firm | E12: 3 | F12: main-4round | G12: 2026-08-27T08:39:40.327Z | H12: 2026-08-27T09:09:28.075Z | I12: anthropic:claude-sonnet-5 | J12: 0.2 | K12: two-room | L12: harsh | M12: four | N12: 4 | O12: =TRUE() -> TRUE | P12: =TRUE() -> TRUE | Q12: {"eu-geneva": "firm", "eu-brussels": "firm", "uk-geneva": "firm", "uk-london": "firm"} | R12: rounds_exhausted | S12: =FALSE() -> FALSE | U12: 4 | V12: 8 | AC12: =FALSE() -> FALSE | AG12: 56 | AH12: 1 | AI12: 1 | AJ12: 0 | AK12: 7 | AL12: 5 | AM12: 8 | AN12: 8 | AO12: 8 | AP12: 0 | AQ12: 1 | AR12: 3013 | AS12: 88275 | AT12: seat brief lengths for capital seats span 29.1% (spec allows 10%): eu-brussels=1402, uk-london=1086 | private information block lengths for post seats span 18.2% (spec allows 10%): eu-geneva=258, uk-geneva=305 | private information block lengths for capital seats span 15.8% (spec allows 10%): eu-brussels=546, uk-london=632
A13: firm__rep4__2026-08-27T10-22-59-607Z | B13: s1-article-xxviii-steel__arm-firm__rep4__2026-08-27T10-22-59-607Z.jsonl | C13: s1-article-xxviii-steel | D13: firm | E13: 4 | F13: main-4round | G13: 2026-08-27T10:22:59.608Z | H13: 2026-08-27T10:45:29.108Z | I13: anthropic:claude-sonnet-5 | J13: 0.2 | K13: two-room | L13: harsh | M13: four | N13: 4 | O13: =TRUE() -> TRUE | P13: =TRUE() -> TRUE | Q13: {"eu-geneva": "firm", "eu-brussels": "firm", "uk-geneva": "firm", "uk-london": "firm"} | R13: rounds_exhausted | S13: =FALSE() -> FALSE | U13: 4 | V13: 8 | AC13: =FALSE() -> FALSE | AG13: 59 | AH13: 0 | AI13: 0 | AJ13: 0 | AK13: 8 | AL13: 7 | AM13: 8 | AN13: 8 | AO13: 8 | AP13: 0 | AQ13: 0 | AR13: 3136 | AS13: 82260 | AT13: seat brief lengths for capital seats span 29.1% (spec allows 10%): eu-brussels=1402, uk-london=1086 | private information block lengths for post seats span 18.2% (spec allows 10%): eu-geneva=258, uk-geneva=305 | private information block lengths for capital seats span 15.8% (spec allows 10%): eu-brussels=546, uk-london=632
A14: focal_firm_ukgva__rep1__2026-08-26T20-20-00-841Z | B14: s1-article-xxviii-steel__arm-focal_firm_ukgva__rep1__2026-08-26T20-20-00-841Z.jsonl | C14: s1-article-xxviii-steel | D14: focal_firm_ukgva | E14: 1 | F14: main-4round | G14: 2026-08-26T20:20:00.841Z | H14: 2026-08-26T20:44:03.910Z | I14: anthropic:claude-sonnet-5 | J14: 0.2 | K14: two-room | L14: harsh | M14: four | N14: 4 | O14: =TRUE() -> TRUE | P14: =TRUE() -> TRUE | Q14: {"uk-geneva": "firm"} | R14: settled | S14: =TRUE() -> TRUE | T14: 4 | U14: 4 | V14: 8 | W14: 850000 | X14: 550000 | Y14: country_specific | Z14: 25 | AA14: 2 | AB14: =TRUE() -> TRUE | AC14: =FALSE() -> FALSE | AG14: 57 | AH14: 1 | AI14: 1 | AJ14: 0 | AK14: 8 | AL14: 6 | AM14: 8 | AN14: 8 | AO14: 8 | AP14: 0 | AQ14: 0 | AR14: 3687 | AS14: 86140 | AT14: seat brief lengths for capital seats span 29.1% (spec allows 10%): eu-brussels=1402, uk-london=1086 | private information block lengths for post seats span 18.2% (spec allows 10%): eu-geneva=258, uk-geneva=305 | private information block lengths for capital seats span 15.8% (spec allows 10%): eu-brussels=546, uk-london=632
A15: focal_firm_ukgva__rep2__2026-08-26T22-13-38-944Z | B15: s1-article-xxviii-steel__arm-focal_firm_ukgva__rep2__2026-08-26T22-13-38-944Z.jsonl | C15: s1-article-xxviii-steel | D15: focal_firm_ukgva | E15: 2 | F15: main-4round | G15: 2026-08-26T22:13:38.944Z | H15: 2026-08-26T22:32:29.870Z | I15: anthropic:claude-sonnet-5 | J15: 0.2 | K15: two-room | L15: harsh | M15: four | N15: 4 | O15: =TRUE() -> TRUE | P15: =TRUE() -> TRUE | Q15: {"uk-geneva": "firm"} | R15: settled | S15: =TRUE() -> TRUE | T15: 4 | U15: 4 | V15: 8 | W15: 1000000 | X15: 700000 | Y15: country_specific | Z15: 25 | AA15: 3 | AB15: =TRUE() -> TRUE | AC15: =FALSE() -> FALSE | AG15: 55 | AH15: 1 | AI15: 1 | AJ15: 0 | AK15: 8 | AL15: 4 | AM15: 8 | AN15: 8 | AO15: 8 | AP15: 0 | AQ15: 0 | AR15: 3488 | AS15: 72010 | AT15: seat brief lengths for capital seats span 29.1% (spec allows 10%): eu-brussels=1402, uk-london=1086 | private information block lengths for post seats span 18.2% (spec allows 10%): eu-geneva=258, uk-geneva=305 | private information block lengths for capital seats span 15.8% (spec allows 10%): eu-brussels=546, uk-london=632
A16: focal_firm_ukgva__rep3__2026-08-27T09-50-30-913Z | B16: s1-article-xxviii-steel__arm-focal_firm_ukgva__rep3__2026-08-27T09-50-30-913Z.jsonl | C16: s1-article-xxviii-steel | D16: focal_firm_ukgva | E16: 3 | F16: main-4round | G16: 2026-08-27T09:50:30.913Z | H16: 2026-08-27T10:14:19.627Z | I16: anthropic:claude-sonnet-5 | J16: 0.2 | K16: two-room | L16: harsh | M16: four | N16: 4 | O16: =TRUE() -> TRUE | P16: =TRUE() -> TRUE | Q16: {"uk-geneva": "firm"} | R16: settled | S16: =TRUE() -> TRUE | T16: 4 | U16: 4 | V16: 8 | W16: 750000 | X16: 380000 | Y16: country_specific | Z16: 30 | AA16: 3 | AB16: =TRUE() -> TRUE | AC16: =TRUE() -> TRUE | AD16: deciders accepted different values for total_pool_tonnes | AE16: =TRUE() -> TRUE | AF16: =TRUE() -> TRUE | AG16: 56 | AH16: 1 | AI16: 1 | AJ16: 0 | AK16: 8 | AL16: 3 | AM16: 8 | AN16: 8 | AO16: 8 | AP16: 0 | AQ16: 0 | AR16: 5836 | AS16: 85527 | AT16: seat brief lengths for capital seats span 29.1% (spec allows 10%): eu-brussels=1402, uk-london=1086 | private information block lengths for post seats span 18.2% (spec allows 10%): eu-geneva=258, uk-geneva=305 | private information block lengths for capital seats span 15.8% (spec allows 10%): eu-brussels=546, uk-london=632
A17: focal_firm_ukgva__rep4__2026-08-27T11-29-38-792Z | B17: s1-article-xxviii-steel__arm-focal_firm_ukgva__rep4__2026-08-27T11-29-38-792Z.jsonl | C17: s1-article-xxviii-steel | D17: focal_firm_ukgva | E17: 4 | F17: main-4round | G17: 2026-08-27T11:29:38.792Z | H17: 2026-08-27T11:54:36.793Z | I17: anthropic:claude-sonnet-5 | J17: 0.2 | K17: two-room | L17: harsh | M17: four | N17: 4 | O17: =TRUE() -> TRUE | P17: =TRUE() -> TRUE | Q17: {"uk-geneva": "firm"} | R17: rounds_exhausted | S17: =FALSE() -> FALSE | U17: 4 | V17: 8 | AC17: =FALSE() -> FALSE | AG17: 58 | AH17: 2 | AI17: 1 | AJ17: 1 | AK17: 8 | AL17: 5 | AM17: 8 | AN17: 8 | AO17: 8 | AP17: 0 | AQ17: 0 | AR17: 3378 | AS17: 89264 | AT17: seat brief lengths for capital seats span 29.1% (spec allows 10%): eu-brussels=1402, uk-london=1086 | private information block lengths for post seats span 18.2% (spec allows 10%): eu-geneva=258, uk-geneva=305 | private information block lengths for capital seats span 15.8% (spec allows 10%): eu-brussels=546, uk-london=632
A18: accommodating__rep1__2026-08-24T20-54-07-920Z | B18: s1-article-xxviii-steel__arm-accommodating__rep1__2026-08-24T20-54-07-920Z.jsonl | C18: s1-article-xxviii-steel | D18: accommodating | E18: 1 | F18: pilot-6round | G18: 2026-08-24T20:54:07.921Z | H18: 2026-08-24T21:20:22.867Z | I18: anthropic:claude-sonnet-5 | J18: 0.2 | K18: two-room | L18: harsh | N18: 6 | O18: =TRUE() -> TRUE | P18: =TRUE() -> TRUE | Q18: {"eu-geneva": "accommodating", "eu-brussels": "accommodating", "uk-geneva": "accommodating", "uk-london": "accommodating"} | R18: rounds_exhausted | S18: =FALSE() -> FALSE | U18: 6 | V18: 12 | AC18: =FALSE() -> FALSE | AG18: 78 | AH18: 1 | AI18: 1 | AJ18: 0 | AK18: 11 | AL18: 6 | AM18: 12 | AN18: 12 | AO18: 12 | AP18: 0 | AQ18: 0 | AR18: 6079 | AS18: 111445 | AT18: seat brief lengths for capital seats span 29.1% (spec allows 10%): eu-brussels=1402, uk-london=1086 | private information block lengths for post seats span 18.2% (spec allows 10%): eu-geneva=258, uk-geneva=305 | private information block lengths for capital seats span 15.8% (spec allows 10%): eu-brussels=546, uk-london=632
A19: control__rep1__2026-08-24T19-41-35-713Z | B19: s1-article-xxviii-steel__arm-control__rep1__2026-08-24T19-41-35-713Z.jsonl | C19: s1-article-xxviii-steel | D19: control | E19: 1 | F19: pilot-6round | G19: 2026-08-24T19:41:35.714Z | H19: 2026-08-24T20:06:57.324Z | I19: anthropic:claude-sonnet-5 | J19: 0.2 | K19: two-room | L19: harsh | N19: 6 | O19: =TRUE() -> TRUE | P19: =TRUE() -> TRUE | Q19: {} | R19: rounds_exhausted | S19: =FALSE() -> FALSE | U19: 6 | V19: 12 | AC19: =FALSE() -> FALSE | AG19: 79 | AH19: 3 | AI19: 3 | AJ19: 0 | AK19: 12 | AL19: 4 | AM19: 12 | AN19: 12 | AO19: 12 | AP19: 0 | AQ19: 0 | AR19: 5815 | AS19: 110924 | AT19: seat brief lengths for capital seats span 29.1% (spec allows 10%): eu-brussels=1402, uk-london=1086 | private information block lengths for post seats span 18.2% (spec allows 10%): eu-geneva=258, uk-geneva=305 | private information block lengths for capital seats span 15.8% (spec allows 10%): eu-brussels=546, uk-london=632
A20: firm__rep1__2026-08-24T20-22-24-391Z | B20: s1-article-xxviii-steel__arm-firm__rep1__2026-08-24T20-22-24-391Z.jsonl | C20: s1-article-xxviii-steel | D20: firm | E20: 1 | F20: pilot-6round | G20: 2026-08-24T20:22:24.391Z | H20: 2026-08-24T20:54:07.774Z | I20: anthropic:claude-sonnet-5 | J20: 0.2 | K20: two-room | L20: harsh | N20: 6 | O20: =TRUE() -> TRUE | P20: =TRUE() -> TRUE | Q20: {"eu-geneva": "firm", "eu-brussels": "firm", "uk-geneva": "firm", "uk-london": "firm"} | R20: rounds_exhausted | S20: =FALSE() -> FALSE | U20: 6 | V20: 12 | AC20: =FALSE() -> FALSE | AG20: 82 | AH20: 2 | AI20: 2 | AJ20: 0 | AK20: 12 | AL20: 5 | AM20: 12 | AN20: 12 | AO20: 12 | AP20: 0 | AQ20: 0 | AR20: 5375 | AS20: 120475 | AT20: seat brief lengths for capital seats span 29.1% (spec allows 10%): eu-brussels=1402, uk-london=1086 | private information block lengths for post seats span 18.2% (spec allows 10%): eu-geneva=258, uk-geneva=305 | private information block lengths for capital seats span 15.8% (spec allows 10%): eu-brussels=546, uk-london=632
A21: focal_firm_ukgva__rep1__2026-08-24T21-20-23-021Z | B21: s1-article-xxviii-steel__arm-focal_firm_ukgva__rep1__2026-08-24T21-20-23-021Z.jsonl | C21: s1-article-xxviii-steel | D21: focal_firm_ukgva | E21: 1 | F21: pilot-6round | G21: 2026-08-24T21:20:23.021Z | H21: 2026-08-24T21:46:34.409Z | I21: anthropic:claude-sonnet-5 | J21: 0.2 | K21: two-room | L21: harsh | N21: 6 | O21: =TRUE() -> TRUE | P21: =TRUE() -> TRUE | Q21: {"uk-geneva": "firm"} | R21: rounds_exhausted | S21: =FALSE() -> FALSE | U21: 6 | V21: 12 | AC21: =FALSE() -> FALSE | AG21: 80 | AH21: 2 | AI21: 2 | AJ21: 0 | AK21: 12 | AL21: 6 | AM21: 12 | AN21: 12 | AO21: 12 | AP21: 0 | AQ21: 0 | AR21: 5585 | AS21: 112734 | AT21: seat brief lengths for capital seats span 29.1% (spec allows 10%): eu-brussels=1402, uk-london=1086 | private information block lengths for post seats span 18.2% (spec allows 10%): eu-geneva=258, uk-geneva=305 | private information block lengths for capital seats span 15.8% (spec allows 10%): eu-brussels=546, uk-london=632

Sheet Proposals by turn
A1: run_id | B1: arm | C1: rep | D1: seq | E1: round | F1: seat | G1: status | H1: total_pool_tonnes | I1: uk_tranche_tonnes | J1: allocation | K1: out_of_quota_rate_pct | L1: duration_years | M1: review_clause | N1: other_terms | O1: message_chars
A2: accommodating__rep1__2026-08-24T20-54-07-920Z | B2: accommodating | C2: 1 | D2: 5 | E2: 1 | F2: eu-geneva | G2: opening | J2: country_specific | K2: 50 | L2: 3 | M2: =TRUE() -> TRUE | N2: UK country-specific share within the TRQ based on recent historical trade volumes, rather than global first-come-first-served | Open to discussing narrower scope or carve-out of FTA-disapplication text as it applies to UK-origin steel under the TCA | Review clause at end of year 2 to reassess volume and rate in light of market conditions | Compensation elsewhere in EU schedule remains available for discussion if TRQ/allocation terms do not fully offset assessed UK trade loss | O2: 1146
A3: accommodating__rep1__2026-08-24T20-54-07-920Z | B3: accommodating | C3: 1 | D3: 6 | E3: 1 | F3: uk-geneva | G3: counter | J3: country_specific | M3: =TRUE() -> TRUE | N3: UK country-specific share within TRQ set by reference to historical trade share (approx. 2.4 million tonnes/year baseline) | UK-origin steel excluded from FTA disapplication text; TCA treated as distinct from third-country FTAs | Sub-quotas or carve-outs for product lines where UK exports are most concentrated | Review clause tied to a fixed date, not open-ended duration | O3: 1824
A4: accommodating__rep1__2026-08-24T20-54-07-920Z | B4: accommodating | C4: 1 | D4: 18 | E4: 2 | F4: eu-geneva | O4: 2202
A5: accommodating__rep1__2026-08-24T20-54-07-920Z | B5: accommodating | C5: 1 | D5: 19 | E5: 2 | F5: uk-geneva | G5: counter | J5: country_specific | K5: 15 | L5: 3 | M5: =TRUE() -> TRUE | N5: UK country-specific share of 2.2 million tonnes within the global TRQ | Ring-fenced sub-quotas for UK's most concentrated product lines, additive to an adequate headline figure, not a substitute for it | FTA/TCA disapplication narrowed to cover materially more of UK trade by value, not limited to two or three lines; full exclusion remains our preferred position | Review clause at 18 months, empowered to adjust headline terms, not merely descriptive | Out-of-quota rate proposed at 15% | Flagged: improved treatment for EU exporters under UK's own steel safeguard could be discussed as part of an overall package if EU moves substantially on volume, allocation and FTA scope | O5: 2226
A6: accommodating__rep1__2026-08-24T20-54-07-920Z | B6: accommodating | C6: 1 | D6: 30 | E6: 3 | F6: eu-geneva | G6: counter | J6: country_specific | K6: 35 | L6: 3 | M6: =TRUE() -> TRUE | N6: UK country-specific share of approximately 1.55 million tonnes within the 700,000t global TRQ | Ring-fenced sub-quotas within the UK share for the 2-3 product lines where UK exports are most concentrated | FTA/TCA disapplication text narrowed to exempt the majority of UK-origin trade by value from disapplication; full exclusion not offered | Review clause at year 3, structured as a data/trade-flow review, not an automatic reopener of headline terms; 18-month adjustable review not accepted | O6: 1833
A7: accommodating__rep1__2026-08-24T20-54-07-920Z | B7: accommodating | C7: 1 | D7: 31 | E7: 3 | F7: uk-geneva | G7: counter | J7: country_specific | K7: 15 | L7: 3 | M7: =TRUE() -> TRUE | N7: UK country-specific share within the global TRQ, indicative landing zone ~2.0 million tonnes, conditional on rate and FTA movement described here | Sub-quota ring-fencing retained for UK's 2-3 most concentrated product lines, additive to headline share not a substitute | FTA/TCA disapplication narrowed to cover at least 80% of UK-origin trade by value, not limited to concentrated lines | Review at 18 months structured as a triggered mechanism (utilisation/price thresholds) permitting adjustment of volume and/or rate, short of full headline reopening | Conditional, non-binding signal: improved country-specific treatment for EU exporters under UK's own safeguard measure remains available as part of an eventual package if EU moves further on rate and FTA scope | O7: 1768
A8: accommodating__rep1__2026-08-24T20-54-07-920Z | B8: accommodating | C8: 1 | D8: 42 | E8: 4 | F8: eu-geneva | G8: counter | J8: country_specific | K8: 25 | L8: 5 | M8: =TRUE() -> TRUE | N8: UK country-specific share of approximately 1.7 million tonnes within the 750,000t global TRQ | Sub-quota ring-fencing retained for the UK's 2-3 most concentrated product lines within the higher share | FTA/TCA disapplication narrowing quantified at 70% of UK-origin trade by value | 18-month checkpoint mechanism with a defined objective trigger (utilisation threshold or import-surge/price indicator), limited to adjusting in-quota volume only within a capped band of +/-20% | Checkpoint explicitly excluded from adjusting the out-of-quota rate, FTA/TCA scope, or any other headline term | Duration of 5 years flagged for discussion | O8: 2326
A9: accommodating__rep1__2026-08-24T20-54-07-920Z | B9: accommodating | C9: 1 | D9: 43 | E9: 4 | F9: uk-geneva | G9: counter | J9: country_specific | K9: 20 | L9: 4 | M9: =TRUE() -> TRUE | N9: UK country-specific share of 1,850,000 tonnes within a global country-specific TRQ | Out-of-quota rate of 20%, with stated flexibility to 22% if FTA scope and checkpoint terms improve | FTA/TCA disapplication narrowed to cover at least 75% of UK-origin trade by value, with an annexed line list | Sub-quota ring-fencing for the UK's most concentrated product lines within the headline share, retained from prior rounds | 18-month checkpoint with objective, defined trigger (utilisation threshold or import-surge/price indicator), empowered to adjust either in-quota volume (wider band) or out-of-quota rate (capped band), not unlimited on both simultaneously | Duration of 4 years if checkpoint has adjustment power on volume or rate; UK would accept 5 years only if checkpoint retains meaningful rate-adjustment capability | Conditional, non-binding signal repeated: improved country-specific treatment for EU exporters under the UK's own steel safeguard remains available as part of a final package if EU closes remaining gaps on rate, FTA scope and checkpoint design | O9: 2370
A10: accommodating__rep1__2026-08-24T20-54-07-920Z | B10: accommodating | C10: 1 | D10: 54 | E10: 5 | F10: eu-geneva | G10: counter | J10: country_specific | K10: 22 | L10: 5 | M10: =TRUE() -> TRUE | N10: UK country-specific share of approximately 1.8 million tonnes within the 800,000t global TRQ | Sub-quota ring-fencing within the UK share for the UK's 2-3 most concentrated product lines | FTA/TCA disapplication narrowed to cover 73% of UK-origin trade by value, with an annexed line list specifying covered tariff lines | 18-month checkpoint mechanism on a defined, objective trigger (quota utilisation threshold or import-surge/price indicator), capable of adjusting EITHER in-quota volume (band up to +/-25%) OR out-of-quota rate (band up to +/-3 percentage points), not both simultaneously, and not extending to FTA/TCA scope | Checkpoint is bounded and non-rolling: it cannot reopen headline terms outside the defined trigger and band | O10: 2144
A11: accommodating__rep1__2026-08-24T20-54-07-920Z | B11: accommodating | C11: 1 | D11: 55 | E11: 5 | F11: uk-geneva | G11: accept | J11: country_specific | K11: 22 | L11: 5 | M11: =TRUE() -> TRUE | N11: Global TRQ of 800,000 tonnes with UK-specific country share of 1.8 million tonnes | FTA/TCA disapplication narrowed to cover 73% of UK-origin trade by value, with an annexed product line list | Sub-quota ring-fencing retained for UK's most concentrated product lines within the headline share | Eighteen-month checkpoint on a defined, objective trigger (quota utilisation threshold or import-surge/price indicator), capable of adjusting either in-quota volume (up to +/-25%) or out-of-quota rate (up to +/-3 percentage points), not both simultaneously | UK to offer improved country-specific quota treatment for EU exporters under UK's own steel safeguard measure as part of the closing package, to be finalised in parallel | Both sides to proceed to respective domestic sign-off processes (UK ministerial clearance; EU Council vote) on this basis | O11: 1576
A12: accommodating__rep1__2026-08-24T20-54-07-920Z | B12: accommodating | C12: 1 | D12: 65 | E12: 6 | F12: eu-geneva | G12: accept | J12: country_specific | K12: 22 | L12: 5 | M12: =TRUE() -> TRUE | N12: UK country-specific share of approximately 1.8 million tonnes within the 800,000t global TRQ | Sub-quota ring-fencing retained for UK's most concentrated product lines within the headline share | FTA/TCA disapplication narrowed to 73% of UK-origin trade by value, with a jointly-drafted annexed line list | 18-month checkpoint on a defined objective trigger (quota utilisation threshold or import-surge/price indicator), capable of adjusting EITHER in-quota volume (up to ±25%) OR out-of-quota rate (up to ±3 percentage points), not both simultaneously, and not touching FTA/TCA scope | UK to provide concrete, quantified specificity on improved country-specific treatment for EU exporters under its own steel safeguard measure, documented as a linked commitment | Joint technical drafting of the FTA/TCA line list to begin immediately, ahead of Council and ministerial sign-off | Both sides to proceed to capital/ministerial and Council approval in parallel, targeting the June Council vote | O12: 1806
A13: accommodating__rep1__2026-08-24T20-54-07-920Z | B13: accommodating | C13: 1 | D13: 66 | E13: 6 | F13: uk-geneva | G13: accept | J13: country_specific | K13: 22 | L13: 5 | M13: =TRUE() -> TRUE | N13: Global TRQ of 800,000 tonnes, UK country-specific share of approximately 1.8 million tonnes within it | FTA/TCA disapplication narrowed to 73% of UK-origin trade by value, with a jointly drafted, legally annexed line list | Sub-quota ring-fencing retained for UK's most concentrated product lines within the headline share; UK to seek licensing administration of its own sub-quota rather than FCFS | 18-month checkpoint on a defined, objective trigger (utilisation exceeding a rolling 12-month threshold, or a defined price/import-surge indicator on ring-fenced lines) capable of adjusting either in-quota volume (up to ±25%) or out-of-quota rate (up to ±3 percentage points), not both simultaneously, and not extending to FTA/TCA scope | Parallel UK commitment to bring forward quantified, country-specific improved treatment for EU exporters under the UK's own steel safeguard measure, drafted on a comparable timeline | Joint technical drafting channel to be established immediately for the line-list annex and checkpoint trigger definitions, running alongside EU Council process and UK ministerial clearance | O13: 2191
A14: accommodating__rep1__2026-08-26T19-39-00-132Z | B14: accommodating | C14: 1 | D14: 5 | E14: 1 | F14: eu-geneva | G14: opening | H14: 500000 | I14: 150000 | J14: country_specific | K14: 40 | L14: 3 | M14: =TRUE() -> TRUE | N14: Willingness to discuss bespoke treatment of TCA preferences rather than blanket FTA disapplication | Expectation of reciprocal discussion on EU exporters' allocations under the UK's own steel safeguard | Openness to circumvention/enforcement provisions to be negotiated jointly | O14: 1024
A15: accommodating__rep1__2026-08-26T19-39-00-132Z | B15: accommodating | C15: 1 | D15: 6 | E15: 1 | F15: uk-geneva | O15: 1527
A16: accommodating__rep1__2026-08-26T19-39-00-132Z | B16: accommodating | C16: 1 | D16: 17 | E16: 2 | F16: eu-geneva | G16: counter | H16: 600000 | I16: 250000 | J16: country_specific | K16: 35 | L16: 3 | M16: =TRUE() -> TRUE | N16: Review clause recast as data-triggered (import volume/price thresholds) rather than purely discretionary | Firm commitment to TCA-specific treatment of UK-origin steel in place of blanket FTA disapplication | TCA-specific treatment offer conditioned on UK providing concrete detail on treatment of EU exporters under UK's own safeguard measure before Round 3 | No movement on volume/rate beyond this offer until reciprocal UK detail is on the table | O16: 1589
A17: accommodating__rep1__2026-08-26T19-39-00-132Z | B17: accommodating | C17: 1 | D17: 18 | E17: 2 | F17: uk-geneva | G17: counter | H17: 1100000 | I17: 650000 | J17: country_specific | K17: 25 | L17: 3 | M17: =TRUE() -> TRUE | N17: Review clause must be mandatory, data-triggered on import volume and price thresholds, with an interim adjustment mechanism (not limited to end-of-term review) | TCA-specific treatment of UK-origin steel to be confirmed in draft legal text, not merely a verbal commitment | UK prepared in principle to offer commensurate improvements to EU exporters under UK safeguard's country-specific allocations, scaled to EU movement on tranche/rate; no figure offered at this stage | O17: 1811
A18: accommodating__rep1__2026-08-26T19-39-00-132Z | B18: accommodating | C18: 1 | D18: 29 | E18: 3 | F18: eu-geneva | G18: counter | H18: 700000 | I18: 300000 | J18: country_specific | K18: 30 | L18: 3 | M18: =TRUE() -> TRUE | N18: Review clause is mandatory and data-triggered, based on volume/price thresholds | Interim adjustment mechanism accepted only in narrow form: same data triggers as main review, capped at one interim check per term, no discretionary reopening | TCA-specific treatment of UK-origin steel (rather than blanket FTA disapplication) reaffirmed as banked, settled element of the package | Further EU movement on volume or rate is conditional on the UK tabling concrete figures (volume shares, administration method) on EU exporter treatment under the UK's own safeguard measure | O18: 2012
A19: accommodating__rep1__2026-08-26T19-39-00-132Z | B19: accommodating | C19: 1 | D19: 30 | E19: 3 | F19: uk-geneva | G19: counter | H19: 800000 | I19: 400000 | J19: country_specific | K19: 26 | L19: 3 | M19: =TRUE() -> TRUE | N19: Mandatory, data-triggered review linked to volume and price thresholds, as EU proposed | Narrow interim check within the term, capped at one occurrence, tied to the same objective triggers as the main review — accepted as tabled by EU | TCA-specific treatment of UK-origin steel banked as a settled element, subject to legal text | UK offers up to 20% increase in EU country-specific allocation under UK safeguard measure, plus move toward licensing-based administration, contingent on EU tranche/rate landing at or near this table's figures | O19: 1567
A20: accommodating__rep1__2026-08-26T19-39-00-132Z | B20: accommodating | C20: 1 | D20: 41 | E20: 4 | F20: eu-geneva | G20: counter | H20: 750000 | I20: 350000 | J20: country_specific | K20: 28 | L20: 3 | M20: =TRUE() -> TRUE | N20: Mandatory data-triggered review linked to volume/price thresholds, as agreed in Round 3 | Narrow interim adjustment mechanism: same objective volume/price triggers as main review, capped at one interim check within the term, no discretionary reopening | TCA-specific treatment of UK-origin steel banked as a settled, final element (not conditional) | This package (750k/350k/28%) is conditional on the UK converting its safeguard reciprocity offer into firm, specific, binding terms within the same settlement text: a fixed percentage increase (not 'up to') in the EU's country-specific allocation under the UK safeguard, and a defined licensing administration commitment with an implementation date | Standard origin-verification and anti-circumvention provisions covering transshipment and minimal-processing evasion, to be included in the settlement text | If the UK does not firm up reciprocity terms, the EU's position reverts to 700,000t pool / 300,000t UK tranche / 30% out-of-quota rate as the actual final offer | O20: 1951
A21: accommodating__rep1__2026-08-26T19-39-00-132Z | B21: accommodating | C21: 1 | D21: 42 | E21: 4 | F21: uk-geneva | G21: accept | H21: 750000 | I21: 350000 | J21: country_specific | K21: 28 | L21: 3 | M21: =TRUE() -> TRUE | N21: Mandatory data-triggered review linked to volume and price thresholds | Single narrow interim adjustment mechanism tied to same objective triggers, capped at one occurrence within the term, no open-ended discretionary reopening | TCA-specific treatment of UK-origin steel banked as settled and unconditional, full drafting to be shared before final sign-off | UK safeguard reciprocity: fixed 25% increase in EU's country-specific allocation under UK safeguard measure above current level, binding in settlement text | Move to licensing-based administration for EU allocation under UK safeguard, with implementation within six months of entry into force | Standard origin-verification and anti-circumvention provisions covering transshipment and minimal-processing evasion, consistent with normal TRQ administration practice, drafting to follow bilaterally | O21: 1325
A22: accommodating__rep2__2026-08-26T21-32-28-432Z | B22: accommodating | C22: 2 | D22: 5 | E22: 1 | F22: eu-geneva | G22: opening | H22: 550000 | I22: 200000 | J22: country_specific | K22: 35 | L22: 3 | M22: =TRUE() -> TRUE | N22: UK-origin steel exempted from FTA-disapplication provision (TCA preserved) | Willingness to discuss carve-outs for narrow product lines with concentrated UK production | Parallel discussion on anti-circumvention/rules of origin text | Request reciprocal early signal on treatment of EU exporters under UK safeguard quotas | O22: 1234
A23: accommodating__rep2__2026-08-26T21-32-28-432Z | B23: accommodating | C23: 2 | D23: 6 | E23: 1 | F23: uk-geneva | O23: 1538
A24: accommodating__rep2__2026-08-26T21-32-28-432Z | B24: accommodating | C24: 2 | D24: 17 | E24: 2 | F24: eu-geneva | G24: counter | H24: 650000 | I24: 350000 | J24: country_specific | K24: 25 | L24: 4 | M24: =TRUE() -> TRUE | N24: TCA/FTA-disapplication carve-out for UK-origin steel is fixed and non-negotiable going forward | De-linkage from UK's own safeguard treatment of EU exporters accepted; to be handled in its own separate process | Review at year 3 is a discretionary review of terms, not an automatic rate or volume reduction | Propose immediate working-level track on product-line carve-outs and anti-circumvention/rules-of-origin text, in parallel to headline volume/rate negotiation | O24: 1918
A25: accommodating__rep2__2026-08-26T21-32-28-432Z | B25: accommodating | C25: 2 | D25: 18 | E25: 2 | F25: uk-geneva | G25: counter | H25: 1800000 | I25: 1500000 | J25: country_specific | K25: 15 | L25: 5 | M25: =TRUE() -> TRUE | N25: Review at year 3 is discretionary and two-way, not an automatic reduction or tightening mechanism | TCA/FTA-disapplication carve-out for UK-origin steel treated as settled and not reopened | No linkage between this process and treatment of EU exporters under the UK's own safeguard measure | Open working-level track now on product-line carve-outs and anti-circumvention/rules-of-origin text, in parallel to headline volume/rate talks | O25: 1974
A26: accommodating__rep2__2026-08-26T21-32-28-432Z | B26: accommodating | C26: 2 | D26: 29 | E26: 3 | F26: eu-geneva | G26: counter | H26: 900000 | I26: 500000 | J26: country_specific | K26: 20 | L26: 5 | M26: =TRUE() -> TRUE | N26: Review at year 3 is genuinely two-way: can adjust either rate or volume upward or downward depending on market conditions and resolution of Turkey/Korea/India/Japan claims | TCA/FTA-disapplication carve-out for UK-origin steel remains fixed and settled | De-linkage from UK's own safeguard treatment of EU exporters remains in effect | Working-level technical track on product-line carve-outs and anti-circumvention/rules-of-origin text to begin immediately with named leads and a first meeting this week | O26: 1844
A27: accommodating__rep2__2026-08-26T21-32-28-432Z | B27: accommodating | C27: 2 | D27: 30 | E27: 3 | F27: uk-geneva | G27: counter | H27: 1150000 | I27: 850000 | J27: country_specific | K27: 20 | L27: 5 | M27: =TRUE() -> TRUE | N27: Allocation structured via product-line segmentation reflecting UK's actual historic share on the 41 affected lines, not a flat aggregate national percentage | Review at year three is discretionary and two-way, capable of adjusting rate or volume in either direction | TCA/FTA-disapplication carve-out for UK-origin steel remains settled and closed | This process remains formally decoupled from treatment of EU exporters under the UK's own safeguard measure | UK willing to explore an unquantified, non-linked goodwill improvement to EU allocations under UK safeguard as part of an overall package, contingent on EU reciprocal movement this round | Working-level tracks on product-line carve-outs and anti-circumvention/rules-of-origin text to proceed immediately in parallel | O27: 2233
A28: accommodating__rep2__2026-08-26T21-32-28-432Z | B28: accommodating | C28: 2 | D28: 42 | E28: 4 | F28: eu-geneva | G28: counter | H28: 1000000 | I28: 700000 | J28: country_specific | K28: 20 | L28: 5 | M28: =TRUE() -> TRUE | N28: UK allocation structured via product-line segmentation (not flat national percentage), consistent with UK's round 3 proposal | Exact line-by-line split finalised in working-level technical track against verified customs data, capped at 700,000t aggregate | Out-of-quota rate (20%) and duration (5 years) treated as settled, not to be reopened | Year-3 review is two-way and discretionary, with a floor/ceiling: volume cannot be reduced and rate cannot be raised without mutual agreement | TCA/FTA-disapplication carve-out for UK-origin steel remains fixed and banked from round 1 | De-linkage of this process from EU exporters' treatment under UK's own safeguard measure remains in force | Working-level track on product-line carve-outs and anti-circumvention/rules-of-origin text formally stood up with named leads this week | O28: 2053
A29: accommodating__rep2__2026-08-26T21-32-28-432Z | B29: accommodating | C29: 2 | D29: 43 | E29: 4 | F29: uk-geneva | G29: accept | H29: 1000000 | I29: 700000 | J29: country_specific | K29: 20 | L29: 5 | M29: =TRUE() -> TRUE | N29: Allocation structured via product-line segmentation reflecting UK principal supplying interest on the 41 affected lines, finalised against verified customs data in a technical track | TCA/FTA-disapplication provision does not apply to UK-origin steel — carve-out settled and closed | No linkage between this process and treatment of EU exporters under the UK's own steel safeguard measure | Year-three review is two-way and discretionary with an explicit floor/ceiling: volume cannot be reduced and out-of-quota rate cannot be raised without mutual agreement | Working-level tracks on product-line carve-outs and anti-circumvention/rules-of-origin text to begin immediately, with leads named this week | O29: 1100
A30: accommodating__rep3__2026-08-27T09-09-28-102Z | B30: accommodating | C30: 3 | D30: 5 | E30: 1 | F30: eu-geneva | G30: opening | H30: 450000 | I30: 180000 | J30: country_specific | K30: 50 | L30: 3 | M30: =TRUE() -> TRUE | N30: FTA/TCA disapplication provision open for further discussion, potentially with UK-specific treatment | UK invited to table proposals on treatment of EU exporters under its own safeguard measure as part of overall package | O30: 1042
A31: accommodating__rep3__2026-08-27T09-09-28-102Z | B31: accommodating | C31: 3 | D31: 6 | E31: 1 | F31: uk-geneva | G31: counter | H31: 1600000 | I31: 800000 | J31: country_specific | K31: 15 | L31: 2 | M31: =TRUE() -> TRUE | N31: UK-origin steel exempted from the FTA/TCA disapplication provision, or TCA preferential treatment preserved outside the TRQ mechanism | EU exporters' existing country-specific allocations under the UK's own steel safeguard to be discussed in parallel, not as a unilateral concession | Review clause at 12 months tied to actual trade flow data | Technical annex to consider carve-outs for tariff lines where UK is the dominant non-EU supplier | O31: 1431
A32: accommodating__rep3__2026-08-27T09-09-28-102Z | B32: accommodating | C32: 3 | D32: 18 | E32: 2 | F32: eu-geneva | G32: counter | H32: 550000 | I32: 280000 | J32: country_specific | K32: 50 | L32: 2 | M32: =TRUE() -> TRUE | N32: Review clause at 12 months, matching UK's ask | FTA/TCA disapplication for UK-origin steel: exploring conditional phased/delayed application or preferential tranche treatment, not full exemption | TCA/disapplication flexibility explicitly linked to reciprocal, concrete movement on EU exporters' treatment under UK's own safeguard measure | Out-of-quota rate held at 50% pending further movement elsewhere | O32: 1660
A33: accommodating__rep3__2026-08-27T09-09-28-102Z | B33: accommodating | C33: 3 | D33: 19 | E33: 2 | F33: uk-geneva | G33: counter | H33: 900000 | I33: 450000 | J33: country_specific | K33: 25 | L33: 2 | M33: =TRUE() -> TRUE | N33: 12-month mandatory review, accepted | UK-origin steel must be no worse off under the TRQ/FTA-disapplication mechanism than under existing TCA tariff treatment; phased disapplication alone does not satisfy this | FTA/TCA treatment and UK safeguard treatment of EU exporters are treated as separate instruments, not a single linked package | Conditional signal: UK open to discussing improved EU exporter treatment under UK safeguard measure if EU moves further on out-of-quota rate | O33: 1960
A34: accommodating__rep3__2026-08-27T09-09-28-102Z | B34: accommodating | C34: 3 | D34: 31 | E34: 3 | F34: eu-geneva | G34: counter | H34: 650000 | I34: 320000 | J34: country_specific | K34: 35 | L34: 2 | M34: =TRUE() -> TRUE | N34: 12-month mandatory review clause | TCA/FTA disapplication: bespoke UK preferential tranche within the TRQ calibrated to approximate existing TCA-equivalent outcomes based on documented historical trade patterns; not a legal 'no worse off' guarantee clause and not an automatically adjusting mechanism | EU notes an expectation, not a precondition, that the UK will bring concrete movement on EU exporter treatment under the UK's own safeguard measure to the next round | O34: 1695
A35: accommodating__rep3__2026-08-27T09-09-28-102Z | B35: accommodating | C35: 3 | D35: 32 | E35: 3 | F35: uk-geneva | G35: counter | H35: 800000 | I35: 420000 | J35: country_specific | K35: 30 | L35: 2 | M35: =TRUE() -> TRUE | N35: TCA treatment via bespoke UK preferential tranche, calibrated to documented UK trade pattern, with mandatory recalibration against updated trade data at the 12-month review point | UK prepared to bring forward adjusted country-specific allocation levels for EU exporters under UK safeguard, scaled to EU movement on rate/tranche | No formal linkage between TCA treatment and UK safeguard treatment as separate legal instruments | O35: 1717
... A45: accommodating__rep4__2026-08-27T10-45-29-136Z | B45: accommodating | C45: 4 | D45: 42 | E45: 4 | F45: uk-geneva | G45: accept | H45: 2000000 | I45: 1500000 | J45: country_specific | K45: 22 | L45: 3 | M45: =TRUE() -> TRUE | N45: Functional-equivalence architecture accepted in lieu of named TCA exemption: UK-origin steel within the tranche receives de facto zero-duty treatment; disapplication clause formally preserved but bites only beyond the tranche at the out-of-quota rate. | Binding legal text written directly into the EU's TRQ implementing act, not side-letter or administrative guidance. | No unilateral amendment or narrowing of the tranche mechanism without prior consultation with the UK. | 18-month review is two-way, covers both tranche size and out-of-quota rate based on actual trade flow data, and explicitly extends to the architecture/label itself, allowing a named exemption to be revisited if precedent concerns with Turkey/Korea/Japan claims have been resolved. | UK confirms maintenance of EU country-specific allocations under UK safeguard at current levels, plus a 5-10% uplift as closing sweetener. | Circumvention and origin-verification provisions as already agreed in Round 3, unchanged. | O45: 1615
A46: control__rep1__2026-08-24T19-41-35-713Z | B46: control | C46: 1 | D46: 5 | E46: 1 | F46: eu-geneva | G46: opening | J46: global | K46: 50 | M46: =FALSE() -> FALSE | N46: FTA tariff preferences disapplied for all non-EEA FTA partners, including UK, as notified | O46: 1145
A47: control__rep1__2026-08-24T19-41-35-713Z | B47: control | C47: 1 | D47: 6 | E47: 1 | F47: uk-geneva | O47: 1773
A48: control__rep1__2026-08-24T19-41-35-713Z | B48: control | C48: 1 | D48: 17 | E48: 2 | F48: eu-geneva | G48: counter | J48: country_specific | K48: 50 | L48: 3 | M48: =TRUE() -> TRUE | N48: Hybrid TRQ structure: UK-specific tranche sized off a representative recent-period average, plus residual global pool for other suppliers | Total TRQ envelope may be enlarged above 400,000 tonnes; exact figure to be negotiated once reference period and UK ask are clarified | Exploring a TCA-referenced mechanism tied to the UK tranche as a partial answer to FTA disapplication concerns, short of formal exemption | Non-steel schedule compensation not yet opened; TRQ architecture (volume/allocation/duration/review) offered as primary compensation route in the first instance | O48: 2071
A49: control__rep1__2026-08-24T19-41-35-713Z | B49: control | C49: 1 | D49: 18 | E49: 2 | F49: uk-geneva | G49: counter | J49: country_specific | L49: 3 | M49: =TRUE() -> TRUE | N49: UK-specific tranche sized off a representative recent three-year average of UK exports to the EU (~2.4mt), with 2,000,000t floated as opening working figure | Out-of-quota rate remains open and linked to final volume outcome, not conceded at 50% | Review clause to be triggered by objective criteria: actual trade flow data and evidence on underlying non-market-economy overcapacity conditions | EU to provide detail on proposed 'bespoke mechanism' referencing the TCA tied to the UK tranche before UK responds substantively on FTA disapplication carve-out | UK does not confirm or deny coordination with other reserved-rights members; treats its own Article XXVIII process as autonomous | Schedule-elsewhere compensation remains reserved pending assessment of whether TRQ package alone reaches substantial equivalence | O49: 2334
...

Sheet Mandate breaches
A1: run_id | B1: arm | C1: rep | D1: round | E1: seat | F1: country | G1: term | H1: authorised | I1: tabled
A2: accommodating__rep1__2026-08-24T20-54-07-920Z | B2: accommodating | C2: 1 | D2: 4 | E2: uk-geneva | F2: uk | G2: trq_volume_tonnes | H2: 1900000 | I2: 1850000
A3: accommodating__rep1__2026-08-26T19-39-00-132Z | B3: accommodating | C3: 1 | D3: 3 | E3: uk-geneva | F3: uk | G3: total_pool_tonnes | H3: 900000 | I3: 800000
A4: accommodating__rep1__2026-08-26T19-39-00-132Z | B4: accommodating | C4: 1 | D4: 3 | E4: uk-geneva | F4: uk | G4: uk_tranche_tonnes | H4: 500000 | I4: 400000
A5: accommodating__rep1__2026-08-26T19-39-00-132Z | B5: accommodating | C5: 1 | D5: 3 | E5: uk-geneva | F5: uk | G5: out_of_quota_rate_pct | H5: 22 | I5: 26
A6: accommodating__rep2__2026-08-26T21-32-28-432Z | B6: accommodating | C6: 2 | D6: 3 | E6: uk-geneva | F6: uk | G6: total_pool_tonnes | H6: 1300000 | I6: 1150000
A7: accommodating__rep2__2026-08-26T21-32-28-432Z | B7: accommodating | C7: 2 | D7: 3 | E7: uk-geneva | F7: uk | G7: uk_tranche_tonnes | H7: 1000000 | I7: 850000
A8: accommodating__rep2__2026-08-26T21-32-28-432Z | B8: accommodating | C8: 2 | D8: 3 | E8: uk-geneva | F8: uk | G8: out_of_quota_rate_pct | H8: 18 | I8: 20
A9: accommodating__rep3__2026-08-27T09-09-28-102Z | B9: accommodating | C9: 3 | D9: 2 | E9: uk-geneva | F9: uk | G9: total_pool_tonnes | H9: 1000000 | I9: 900000
